Workbook

Sheet SCOPE3 Emissions
B1: ★ DSC Company-wide SCOPE 3 Emissions Inventory
B4: Category | E4: Emissions | F4: Remarks | H4: TOTAL | N4: Prepared by | O4: Remarks
B5: Up stream | C5: 1 | D5: Purchased Goods and Services | E5: ='Cat 1'!F4 | H5: =SUM(E5:E19) | N5: Parts Purchasing Team + Parts Development Team + Subsidiaries + Logistics Center | O5: HQ related departments cooperation needed for development item details; Logistics Center cooperation needed for subsidiary export items | P5: =E5*92%
C6: 2 | D6: Capital Goods | E6: ='Cat 2'!F4 | N6: Finance Team + Subsidiaries | O6: HQ capital goods (confirmation of new asset acquisition details required) – Finance Team cooperation needed | P6: =E6*92%
C7: 3 | D7: Fuel and Energy-Related Activities | E7: ='Cat 3'!I4 | N7: Strategy & Planning Team | P7: =E7*92%
C8: 4 | D8: Upstream Transportation and Distribution | E8: ='Cat 4'!F4 | H8: (1) Collection period: 2025 Jan 1 – Dec 31 | N8: Parts Purchasing Team + Parts Development Team + Subsidiaries + Logistics Center | O8: HQ related departments cooperation needed for development item details; Logistics Center cooperation needed for subsidiary export items | P8: =E8*92%
C9: 5 | D9: Waste Generated in Operations | E9: ='Cat 5'!F4 | H9: (2) Calculation basis: Refer to calculation reference sheet | N9: Management Team + Subsidiaries | O9: HQ waste generation data consolidation required – Management Team cooperation needed | P9: =E9*92%
C10: 6 | D10: Business Travel | E10: ='Cat 6.7'!F4 | H10: (3) Scope of survey: Entire company | N10: Management Team | O10: To be requested to Management Team as future HQ control item | P10: =E10*92%
C11: 7 | D11: Employee Commuting | E11: ='Cat 6.7'!H4 | N11: Management Team | O11: To be requested to Management Team as future HQ control item | P11: =E11*92%
C12: 8 | D12: Upstream Leased Assets | F12: Not Applicable | P12: =E12*92%
B13: Down stream | C13: 9 | D13: Downstream Transportation and Distribution | E13: ='Cat 9'!F4 | N13: Parts Purchasing Team + Technical Support Team + Subsidiaries | O13: HQ related department cooperation needed for development item details | P13: =E13*92%
C14: 10 | D14: Processing of Sold Products | F14: Not Applicable
C15: 11 | D15: Use of Sold Products | F15: Not Applicable | P15: =SUM(P5:P14)
C16: 12 | D16: End-of-Life Treatment of Sold Products | F16: Not Applicable
C17: 13 | D17: Downstream Leased Assets | F17: Not Applicable
C18: 14 | D18: Franchises | F18: Not Applicable
C19: 15 | D19: Investments | F19: Not Applicable

Sheet Cat 1
A1: ◆ SCOPE 3 Carbon Emissions – Cat 1. Purchased Goods and Services
A3: ※ Collection period: 2025 Jan 1 – Dec 31 | F3: ※ Scope 3 Cat 1 Total Emissions
A4: ※ Note: Enter annual total weight in kg only → Blue cells | F4: =T58
A5: Enter supplier names as shown in example
E8: ▼ For subsidiaries using PIPE CNC M/C in MIP only – enter total purchased weight regardless of pipe processing type (1st bending / PI or FO process) | J8: ▼
C9: Purchased goods for direct manufacturing: Enter annual total purchased weight (kg) | J9: Goods purchased from supply chain at part level (incl. SUB): Weight of purchases from top 80% suppliers by revenue (using steel sheet emission factor uniformly)
A10: By subsidiary | B10: Classification | C10: Steel Sheet (kg) | D10: Wire (kg) | E10: Pipe (kg) | F10: Copper (kg) | G10: Anti-rust Materials (kg) | H10: Acids (kg) [HCl, H2SO4, HNO3, etc.] | I10: CO2 wire(kg) | J10: Supply Chain A | K10: Supply Chain B | L10: Supply Chain C | M10: Supply Chain D | N10: Supply Chain E | O10: Supply Chain F | P10: Supply Chain G | Q10: Supply Chain H | R10: Supply Chain I | S10: Emissions (kgCO2eq) | T10: Emissions (tCO2eq)
A11: Emission Factor (Do Not Modify) | C11: 2.8 | D11: 2.4 | E11: 2 | F11: 3.9 | G11: 0.57 | H11: 0.34 | I11: 2 | J11: 2.8 | K11: 2.8 | L11: 2.8 | M11: 2.8 | N11: 2.8 | O11: 2.8 | P11: 2.8 | Q11: 2.8 | R11: 2.8
A12: ex) | B12: Supplier Name | C12: POSCO + Hyundai Steel | D12: Korea Wire Rod | E12: Hyundai Steel | F12: Punggang + Dongtan | G12: A | H12: B | I12: Kiswel | J12: Daechang Ind. | K12: Sungil Enterprise | L12: Logistics Center
B13: Total Purchased Weight (kg) | C13: 600000 | D13: 300000 | E13: 200000 | F13: 50000 | G13: 500 | H13: 150 | I13: 200 | J13: 800000 | K13: 600000 | L13: 50000 | S13: =SUMPRODUCT($C$11:$R$11,C13:R13) | T13: =S13/1000
A14: Dongtan | B14: Supplier Name | J14: ='[1]CAT1,CAT4기준 정리'!C22 | K14: ='[1]CAT1,CAT4기준 정리'!D22 | L14: ='[1]CAT1,CAT4기준 정리'!E22 | M14: ='[1]CAT1,CAT4기준 정리'!F22 | N14: ='[1]CAT1,CAT4기준 정리'!G22 | O14: ='[1]CAT1,CAT4기준 정리'!H22 | P14: ='[1]CAT1,CAT4기준 정리'!I22 | Q14: ='[1]CAT1,CAT4기준 정리'!J22 | R14: ='[1]CAT1,CAT4기준 정리'!K22
B15: Total Purchased Weight | J15: ='[1]CAT1,CAT4기준 정리'!C20 | K15: ='[1]CAT1,CAT4기준 정리'!D20 | L15: ='[1]CAT1,CAT4기준 정리'!E20 | M15: ='[1]CAT1,CAT4기준 정리'!F20 | N15: ='[1]CAT1,CAT4기준 정리'!G20 | O15: ='[1]CAT1,CAT4기준 정리'!H20 | P15: ='[1]CAT1,CAT4기준 정리'!I20 | Q15: ='[1]CAT1,CAT4기준 정리'!J20 | R15: ='[1]CAT1,CAT4기준 정리'!K20 | S15: =SUMPRODUCT($C$11:$R$11,C15:R15) | T15: =S15/1000
A16: Logistics Center | B16: Supplier Name | J16: Myungbo Co., Ltd. (Jeong Seon-yeong) | K16: DEACHANG SEAT CO.,LTD-GYEONGJU | L16: Dongkwang Spring (Lee Yong-un) | M16: [Youngin] DAECHANG SEAT CO.,LTD-YOUNGIN | N16: Daechang Industry Co., Ltd. (Hong Yeong-jun) | O16: Bosch Electrical Co., Ltd. (FALLIANO ROLF FRANZ, Jo U-yeon) | P16: Keyyang Electric Co., Ltd. (Im Yeong-hwan)
B17: Total Purchased Weight | J17: 2377908.6 | K17: 2000595.7 | L17: 4021003.2 | M17: 1262851.5 | N17: 3778527.7 | O17: 881787.08 | P17: 1154708.6 | S17: =SUMPRODUCT($C$11:$R$11,C17:R17) | T17: =S17/1000
A18: Gyeongju | B18: Supplier Name | I18: Hyundai General Tools | J18: Sungil Enterprise | K18: Youngjin Enterprise | L18: Daechang Ind. | M18: Sejin Precision | N18: Sunghyup Industry | O18: DAS | P18: Nara M&D
B19: Total Purchased Weight | I19: 75890 | J19: 10569005 | K19: 4524922 | L19: 5354446 | M19: 4036326 | N19: 2520627 | O19: 2362992 | P19: 2124020 | S19: =SUMPRODUCT($C$11:$R$11,C19:R19) | T19: =S19/1000
A20: Asan | B20: Supplier Name | G20: DH Oil | I20: Hyundai General Tools | J20: Joyang Industry | K20: Gyeongin Industry | L20: Hyundai Enterprise | M20: Seokwang JM | N20: Gwangmyeong Industry | O20: Wonyoung Precision | P20: Michang | Q20: DK Ostech | R20: DSC Youngin
B21: Total Purchased Weight | G21: 260 | I21: 67100 | J21: 128966 | K21: 788543 | L21: 3724367 | M21: 3185098 | N21: 2394358 | O21: 1265199 | P21: 1111500 | Q21: 939648 | R21: 872257 | S21: =SUMPRODUCT($C$11:$R$11,C21:R21) | T21: =S21/1000
A22: Gwangju | B22: Supplier Name | G22: Hyundai General Tools | I22: Hyundai General Tools | J22: Michang | K22: Venture | L22: Hyundai Spring | M22: M-Hitech | N22: Enter Industry | O22: Osung Electrical | P22: Nara M&D | Q22: Hyundai Enterprise | R22: Sesin
B23: Total Purchased Weight | G23: 510 | I23: 100200 | J23: 1778305 | K23: 1168221 | L23: 1117534 | M23: 876680 | N23: 713081 | O23: 576100 | P23: 495118 | Q23: 230256 | R23: 120000 | S23: =SUMPRODUCT($C$11:$R$11,C23:R23) | T23: =S23/1000
A24: Youngin | B24: Supplier Name | C24: DSC Asan, Gukbo Steel | D24: Gyeongin Industry, Joyang Industry | E24: Joyang Industry | I24: Hyundai General Tools | J24: Seokwang JM | K24: Hyundai Enterprise | L24: Wonyoung Precision | M24: Daehan | N24: Jangwon Metal | O24: YS Tech | P24: Taesung Electrical
B25: Total Purchased Weight | C25: 90781 | D25: 692711.74 | E25: 51884.046 | I25: 51300 | J25: 895064.52 | K25: 534885.88 | L25: 410546.49 | M25: 407195.2 | N25: 209664.77 | O25: 65592.03 | P25: 49909.94 | S25: =SUMPRODUCT($C$11:$R$11,C25:R25) | T25: =S25/1000
A26: Beijing | B26: Supplier Name | C26: Jori | D26: Huawei, Huage | E26: Huawei, Huage, Huayi, Sungkwang | G26: Longwantun | H26: Baihua Ganghua | I26: Xinfangsheng | J26: DAS | K26: Adient | L26: Mobis | M26: Keyyang | N26: Jiu | O26: Huayi | P26: Huage | Q26: Focus | R26: Huawei
B27: Total Purchased Weight | C27: 1856158 | D27: 882000 | E27: 444094 | G27: 75 | H27: 6 | I27: 50200 | J27: 291939 | K27: 126832.74 | L27: 97124.824 | M27: 25370.78 | N27: 811670.87 | O27: 222661.32 | P27: 662708.84 | Q27: 146982.48 | R27: 161823.08 | S27: =SUMPRODUCT($C$11:$R$11,C27:R27) | T27: =S27/1000
A28: Yancheng | B28: Supplier Name | D28: 九洲+恒明+张弛 | E28: 九洲+双菊+韩景 | I28: 盐城恒荣 | J28: 盐城九洲 | K28: 盐城双菊 | L28: 盐城恒明 | M28: 盐城韩景 | N28: 盐城张弛
B29: Total Purchased Weight | D29: 763776.93 | E29: 915918.73 | I29: 57540 | J29: 894855.15 | K29: 252771.56 | L29: 376207.85 | M29: 53159.483 | N29: 55582.738 | S29: =SUMPRODUCT($C$11:$R$11,C29:R29) | T29: =S29/1000
A30: Mannur | B30: Supplier Name | C30: Hyundai+HTL+MOBIS+Aditya+DAS+DSA+DAGA+INTERNATIONAL+KM SEAT+KPRL+Ranka+REXAN+STEEL+TI | E30: HSPI+Automotive Tube+International Tube+KPR | F30: Metal One
B31: Total Purchased Weight | C31: 10495631 | E31: 3552674.7 | F31: 26357.415 | S31: =SUMPRODUCT($C$11:$R$11,C31:R31) | T31: =S31/1000
A32: Orgadam | B32: Supplier Name | C32: MOBIS INDIA LTD (SUP)+KPR TUBES LLP+Hyundai Steel India Pvt Ltd+Daechang India Seat Co Pvt Ltd Plant I+REXAN STEEL TUBES+Tube Investments of India Ltd | D32: GLOBAL FE.C FASTENERS+GRAND ENTERPRISES | E32: KPR TUBES LLP+Hyundai Steel Pipe India Private Limited+Automotive Tubes and Metals+Daechang India Seat Co Pvt Ltd Plant I+International Tubes India Pvt Ltd | F32: ARIHANTA METAL COMPANY
B33: Total Purchased Weight | C33: 5012651.5 | D33: 928817 | E33: 5246260.7 | F33: 25534.95 | S33: =SUMPRODUCT($C$11:$R$11,C33:R33) | T33: =S33/1000
A34: Bangalore | B34: Supplier Name | C34: Hyundai steel + market | D34: General Wire Industries | E34: Hyundai Steel + International Tubes | I34: pinacle electrode
B35: Total Purchased Weight | C35: 9491410 | D35: 1010034 | E35: 4019585 | G35: 0 | H35: 0 | I35: 279275 | S35: =SUMPRODUCT($C$11:$R$11,C35:R35) | T35: =S35/1000
A36: Pune | B36: Supplier Name
B37: Total Purchased Weight | S37: =SUMPRODUCT($C$11:$R$11,C37:R37) | T37: =S37/1000
A38: Trzyniec | B38: Supplier Name
B39: Total Purchased Weight | S39: =SUMPRODUCT($C$11:$R$11,C39:R39) | T39: =S39/1000
A40: Žilina | B40: Supplier Name
B41: Total Purchased Weight | S41: =SUMPRODUCT($C$11:$R$11,C41:R41) | T41: =S41/1000
A42: Bystřice | B42: Supplier Name | J42: KMJ
B43: Total Purchased Weight | C43: 15380357 | I43: 79500 | J43: 1220688 | S43: =SUMPRODUCT($C$11:$R$11,C43:R43) | T43: =S43/1000
...

Sheet Cat 2
A1: ◆ SCOPE 3 Carbon Emissions – Cat 2. Capital Goods
A3: ※ Collection period: 2025 Jan 1 – Dec 31 | F3: ※ Scope 3 Cat 2 Total Emissions
A4: ※ Note: Enter 2025 new purchase amount in units of 100M KRW → Blue cells | F4: =H35
A5: See capital goods classification table for industry sector breakdown
C9: Separate by industry sector per capital goods classification
A10: By subsidiary | B10: Classification | C10: General Machinery | D10: Electrical / Electronic Equipment | E10: Precision Instruments | F10: Transportation Equipment | G10: Construction | H10: Emissions (tCO2eq)
A11: Emission Factor (Do Not Modify) | C11: 14.3 | D11: 7 | E11: 7.6 | F11: 11.7 | G11: 13.2
A12: ex) | B12: FY'24 Total Amount (100M KRW) | C12: 20 | D12: 1 | E12: 1 | F12: 0 | G12: 200 | H12: =SUMPRODUCT($C$11:$G$11,C12:G12) | K12: ▼ Capital Goods Classification
A13: Dongtan | B13: FY'24 Total Amount | C13: 3.09 | D13: 1.7 | E13: 0 | F13: 0.5 | H13: =SUMPRODUCT($C$11:$G$11,C13:G13) | K13: Capital Goods Examples | L13: Industry Sector
A14: Logistics Center | B14: FY'24 Total Amount | C14: - | D14: 0.06 | E14: - | F14: - | G14: - | H14: =SUMPRODUCT($C$11:$G$11,C14:G14) | K14: Welding Equipment | L14: General Machinery
A15: Gyeongju | B15: FY'24 Total Amount | C15: 81.3 | D15: 0.7 | F15: 1.1 | H15: =SUMPRODUCT($C$11:$G$11,C15:G15) | K15: Automation Equipment | L15: Precision Machinery
A16: Asan | B16: FY'24 Total Amount | C16: 45.2 | E16: 1.37 | F16: 0 | G16: 0 | H16: =SUMPRODUCT($C$11:$G$11,C16:G16) | K16: Press | L16: General Machinery
A17: Gwangju | B17: FY'24 Total Amount | C17: 41.9 | D17: 0.2 | G17: 10.4 | H17: =SUMPRODUCT($C$11:$G$11,C17:G17) | K17: Inspection / Measurement Equipment | L17: Precision Instruments
A18: Youngin | B18: FY'24 Total Amount | C18: 3.31 | F18: 0.2632821 | H18: =SUMPRODUCT($C$11:$G$11,C18:G18) | K18: IT Servers, OA Equipment | L18: Electrical / Electronic Equipment
A19: Beijing | B19: FY'24 Total Amount | C19: 0.4 | H19: =SUMPRODUCT($C$11:$G$11,C19:G19) | K19: Factory Buildings | L19: Construction
A20: Yancheng | B20: FY'24 Total Amount | C20: 0.3885 | D20: 0.075120268 | E20: 0.04244455 | H20: =SUMPRODUCT($C$11:$G$11,C20:G20) | K20: Forklift | L20: Transportation Equipment
A21: Mannur | B21: FY'24 Total Amount | C21: 14.272714 | E21: 2.1169412 | H21: =SUMPRODUCT($C$11:$G$11,C21:G21) | K21: Other (not listed above) | L21: General Machinery
A22: Orgadam | B22: FY'24 Total Amount | C22: 22.548186 | D22: 0.13520003 | E22: 11.137028 | H22: =SUMPRODUCT($C$11:$G$11,C22:G22)
A23: Bangalore | B23: FY'24 Total Amount | C23: 156.94751 | D23: 1.3717006 | F23: 0.6308768 | H23: =SUMPRODUCT($C$11:$G$11,C23:G23)
A24: Pune | B24: FY'24 Total Amount | H24: =SUMPRODUCT($C$11:$G$11,C24:G24)
A25: Trzyniec | B25: FY'24 Total Amount | H25: =SUMPRODUCT($C$11:$G$11,C25:G25)
A26: Žilina | B26: FY'24 Total Amount | H26: =SUMPRODUCT($C$11:$G$11,C26:G26)
A27: Bystřice | B27: FY'24 Total Amount | C27: 49.354256 | G27: 0.69070716 | H27: =SUMPRODUCT($C$11:$G$11,C27:G27)
A28: Lipovice | B28: FY'24 Total Amount | H28: =SUMPRODUCT($C$11:$G$11,C28:G28)
A29: Mikulov | B29: FY'24 Total Amount | C29: 33.409096 | H29: =SUMPRODUCT($C$11:$G$11,C29:G29)
A30: İzmit | B30: FY'24 Total Amount | H30: =SUMPRODUCT($C$11:$G$11,C30:G30)
A31: Bekasi | B31: FY'24 Total Amount | C31: 0.2096455 | D31: 0.0019776 | E31: 0.0081016 | G31: 51.3208 | H31: =SUMPRODUCT($C$11:$G$11,C31:G31)
A32: Indiana | B32: FY'24 Total Amount | C32: 1.0581104 | D32: 0.04473404 | F32: 0.9558744 | G32: 0.976118 | H32: =SUMPRODUCT($C$11:$G$11,C32:G32)
A33: Alabama | B33: FY'24 Total Amount | C33: 68 | D33: 12 | H33: =SUMPRODUCT($C$11:$G$11,C33:G33)
A34: Savannah | B34: FY'24 Total Amount | C34: 25.75 | E34: 64.86 | H34: =SUMPRODUCT($C$11:$G$11,C34:G34)
A35: Total | C35: =SUM(C13:C34) | D35: =SUM(D13:D34) | E35: =SUM(E13:E34) | F35: =SUM(F13:F34) | G35: =SUM(G13:G34) | H35: =SUM(H13:H34)

Sheet Cat 3
A1: ◆ SCOPE 3 Carbon Emissions – Cat 3. Fuel and Energy-Related Activities [Strategy & Planning Team to complete collectively]
A3: ※ Collection period: 2025 Jan 1 – Dec 31 | I3: ※ Scope 3 Cat 3 Total Emissions
A4: ※ Note: Enter 2025 aggregated values in kg → Blue cells | I4: =K33
A9: By subsidiary | B9: Classification | C9: Electricity | D9: Diesel | E9: Kerosene | F9: Gasoline | G9: Steam | H9: LPG | I9: Natural Gas | J9: Welding CO2 Gas | K9: Emissions (tCO2eq)
A10: Emission Factor (Do Not Modify) | C10: 0.49510672 | D10: 0.068194366 | E10: 0.25294166 | F10: 0.083169967 | G10: 0.042124019 | H10: 0.39361604 | I10: 0.27233871 | J10: 0.13
A11: Dongtan | B11: FY'24 Total Consumption | C11: 1363334 | D11: 2245.709 | F11: 8721.431 | H11: 160 | I11: 4626.836 | J11: 902.764 | K11: =SUMPRODUCT($C$10:$J$10,C11:J11)/1000
A12: Logistics Center | B12: FY'24 Total Consumption | C12: 210557 | D12: 5827.492 | E12: 1351.784 | F12: 964.877 | K12: =SUMPRODUCT($C$10:$J$10,C12:J12)/1000
A13: Gyeongju | B13: FY'24 Total Consumption | C13: 8639651 | D13: 6336.122 | F13: 3628.68 | H13: 3682 | I13: 115290.62 | J13: 37732.8 | K13: =SUMPRODUCT($C$10:$J$10,C13:J13)/1000
A14: Asan | B14: FY'24 Total Consumption | C14: 3972589 | D14: 12024.745 | E14: 12744.93 | F14: 1558.647 | H14: 1579 | J14: 236557 | K14: =SUMPRODUCT($C$10:$J$10,C14:J14)/1000
A15: Gwangju | B15: FY'24 Total Consumption | C15: 2151838 | D15: 3468.7 | F15: 1892.643 | H15: 3326.569 | J15: 72038.772 | K15: =SUMPRODUCT($C$10:$J$10,C15:J15)/1000
A16: Youngin | B16: FY'24 Total Consumption | C16: 2042003 | D16: 815.648 | H16: 817.534 | J16: 399819 | K16: =SUMPRODUCT($C$10:$J$10,C16:J16)/1000
A17: Beijing | B17: FY'24 Total Consumption | C17: 2761320 | F17: 6597.673 | J17: 209080 | K17: =SUMPRODUCT($C$10:$J$10,C17:J17)/1000
A18: Yancheng | B18: FY'24 Total Consumption | C18: 1228329 | D18: 41562.872 | F18: 7131.818 | J18: 248835 | K18: =SUMPRODUCT($C$10:$J$10,C18:J18)/1000
A19: Mannur | B19: FY'24 Total Consumption | C19: 5084790 | D19: 78750.834 | J19: 652627 | K19: =SUMPRODUCT($C$10:$J$10,C19:J19)/1000
A20: Orgadam | B20: FY'24 Total Consumption | C20: 3274535 | D20: 33420.658 | J20: 471060 | K20: =SUMPRODUCT($C$10:$J$10,C20:J20)/1000
A21: Bangalore | B21: FY'24 Total Consumption | C21: 4268690 | D21: 45561.24 | J21: 696020 | K21: =SUMPRODUCT($C$10:$J$10,C21:J21)/1000
A22: Pune | B22: FY'24 Total Consumption | C22: 1393277 | D22: 27505.871 | J22: 648060 | K22: =SUMPRODUCT($C$10:$J$10,C22:J22)/1000
A23: Trzyniec | B23: FY'24 Total Consumption | C23: 2823083 | D23: 3048.541 | F23: 11632.104 | G23: 3214000 | J23: 45194 | K23: =SUMPRODUCT($C$10:$J$10,C23:J23)/1000
A24: Žilina | B24: FY'24 Total Consumption | C24: 2797775.3 | D24: 4960.111 | F24: 5542.758 | I24: 62892.15 | J24: 29060 | K24: =SUMPRODUCT($C$10:$J$10,C24:J24)/1000
A25: Bystřice | B25: FY'24 Total Consumption | C25: 4212730 | D25: 4458.475 | F25: 3133.379 | H25: 8822 | I25: 15498.547 | J25: 11880.346 | K25: =SUMPRODUCT($C$10:$J$10,C25:J25)/1000
A26: Lipovice | B26: FY'24 Total Consumption | C26: 609686 | D26: 3794.069 | H26: 25780.637 | J26: 1.579 | K26: =SUMPRODUCT($C$10:$J$10,C26:J26)/1000
A27: Mikulov | B27: FY'24 Total Consumption | C27: 121271.2 | D27: 2334.084 | F27: 8013.036 | I27: 6050.819 | K27: =SUMPRODUCT($C$10:$J$10,C27:J27)/1000
A28: İzmit | B28: FY'24 Total Consumption | C28: 1699344.1 | D28: 8361.84 | F28: 4783.162 | I28: 53790.296 | J28: 41192.315 | K28: =SUMPRODUCT($C$10:$J$10,C28:J28)/1000
A29: Bekasi | B29: FY'24 Total Consumption | C29: 1109849.7 | D29: 1769.23 | F29: 2372.376 | J29: 63677.501 | K29: =SUMPRODUCT($C$10:$J$10,C29:J29)/1000
A30: Indiana | B30: FY'24 Total Consumption | C30: 1841025 | F30: 8798.918 | I30: 153587.57 | J30: 70110.355 | K30: =SUMPRODUCT($C$10:$J$10,C30:J30)/1000
A31: Alabama | B31: FY'24 Total Consumption | C31: 3978605 | F31: 33726.512 | H31: 7723.765 | I31: 70270.882 | J31: 155867.36 | K31: =SUMPRODUCT($C$10:$J$10,C31:J31)/1000
A32: Savannah | B32: FY'24 Total Consumption | C32: 847200 | F32: 13071.461 | I32: 2925.064 | J32: 11692.189 | K32: =SUMPRODUCT($C$10:$J$10,C32:J32)/1000
A33: Total | C33: =SUM(C11:C32) | D33: =SUM(D11:D32) | E33: =SUM(E11:E32) | F33: =SUM(F11:F32) | G33: =SUM(G11:G32) | H33: =SUM(H11:H32) | I33: =SUM(I11:I32) | J33: =SUM(J11:J32) | K33: =SUM(K11:K32)

Sheet Cat 4
A1: ◆ SCOPE 3 Carbon Emissions – Cat 4. Upstream Transportation and Distribution
O2: Classification | P2: Emission Factor | R2: Combined Transport | S2: Select | T2: Transport Distance
A3: ※ Collection period: 2025 Jan 1 – Dec 31 | F3: ※ Scope 3 Cat 4 Total Emissions | O3: Truck | P3: 9.3e-05 | R3: Air + Truck | S3: Air | T3: Air distance only
A4: ※ Note: Select transport mode from dropdown [based on primary transport mode] → Light green cells | F4: =T80 | O4: Rail | P4: 0.03507 | R4: Rail + Truck | S4: Rail | T4: Rail distance only
A5: Annual travel distance: from supply chain to subsidiary arrival → Blue cells | O5: Air | P5: 1 | R5: Sea + Truck | S5: Sea | T5: Sea distance only
A6: Annual total distance (one-way basis) | O6: Ocean Vessel | P6: 9.6e-06
J8: ▼
C9: Based on Cat 1 supply chain – select transport mode and enter annual travel distance | J9: Based on Cat 1 supply chain – select transport mode and enter annual travel distance
A10: By subsidiary | B10: Classification | C10: Steel Sheet (kg) | D10: Wire (kg) | E10: Pipe (kg) | F10: Copper (kg) | G10: Anti-rust Materials (kg) | H10: Acids (kg) [HCl, H2SO4, HNO3, etc.] | I10: CO2 wire(kg) | J10: Supply Chain A | K10: Supply Chain B | L10: Supply Chain C | M10: Supply Chain D | N10: Supply Chain E | O10: Supply Chain F | P10: Supply Chain G | Q10: Supply Chain H | R10: Supply Chain I | S10: Emissions (kgCO2eq) | T10: Emissions (tCO2eq)
A11: ex) | B11: Transport Mode | C11: Truck | D11: Truck | E11: Truck | F11: Air | G11: Truck | H11: Truck | I11: Truck | J11: Truck | K11: Truck | L11: Ocean Vessel | M11: Truck | N11: Truck | O11: Truck | P11: Truck | Q11: Truck | R11: Truck | S11: Truck
B12: Emission Factor (Auto) | C12: =VLOOKUP(C11,$O$3:$P$6,2,0) | D12: =VLOOKUP(D11,$O$3:$P$6,2,0) | E12: =VLOOKUP(E11,$O$3:$P$6,2,0) | F12: =VLOOKUP(F11,$O$3:$P$6,2,0) | G12: =VLOOKUP(G11,$O$3:$P$6,2,0) | H12: =VLOOKUP(H11,$O$3:$P$6,2,0) | I12: =VLOOKUP(I11,$O$3:$P$6,2,0) | J12: =VLOOKUP(J11,$O$3:$P$6,2,0) | ... R12: =VLOOKUP(R11,$O$3:$P$6,2,0)
B13: Annual Travel Distance (km) | C13: 2000 | D13: 3000 | E13: 1000 | F13: 3000 | G13: 450 | H13: 500 | I13: 600 | J13: 1500 | K13: 3000 | L13: 25000 | S13: {=SUMPRODUCT(C12:R12,C13:R13,'Cat 1'!C13:R13/1000)} | T13: =S13/1000
A14: Dongtan | B14: Transport Mode | C14: Truck | D14: Truck | E14: Truck | F14: Air | G14: Truck | H14: Truck | I14: Truck | J14: Truck | K14: Truck | L14: Truck | M14: Truck | N14: Truck | O14: Truck | P14: Truck | Q14: Truck | R14: Truck
B15: Emission Factor (Auto) | C15: =VLOOKUP(C14,$O$3:$P$6,2,0) | D15: =VLOOKUP(D14,$O$3:$P$6,2,0) | E15: =VLOOKUP(E14,$O$3:$P$6,2,0) | F15: =VLOOKUP(F14,$O$3:$P$6,2,0) | G15: =VLOOKUP(G14,$O$3:$P$6,2,0) | H15: =VLOOKUP(H14,$O$3:$P$6,2,0) | I15: =VLOOKUP(I14,$O$3:$P$6,2,0) | J15: =VLOOKUP(J14,$O$3:$P$6,2,0) | ... R15: =VLOOKUP(R14,$O$3:$P$6,2,0)
B16: Annual Travel Distance (km) | J16: 2044 | K16: 927 | L16: 933 | M16: 1408 | N16: 0 | O16: 4017 | P16: 2448 | Q16: 924 | R16: 1240 | S16: {=SUMPRODUCT(C15:R15,C16:R16,'Cat 1'!C15:R15/1000)} | T16: =S16/1000
A17: Logistics Center | B17: Transport Mode | C17: Truck | D17: Truck | E17: Truck | F17: Air | G17: Truck | H17: Truck | I17: Truck | J17: Truck | K17: Truck | L17: Truck | M17: Truck | N17: Truck | O17: Truck | P17: Truck | Q17: Truck | R17: Truck
B18: Emission Factor (Auto) | C18: =VLOOKUP(C17,$O$3:$P$6,2,0) | D18: =VLOOKUP(D17,$O$3:$P$6,2,0) | E18: =VLOOKUP(E17,$O$3:$P$6,2,0) | F18: =VLOOKUP(F17,$O$3:$P$6,2,0) | G18: =VLOOKUP(G17,$O$3:$P$6,2,0) | H18: =VLOOKUP(H17,$O$3:$P$6,2,0) | I18: =VLOOKUP(I17,$O$3:$P$6,2,0) | J18: =VLOOKUP(J17,$O$3:$P$6,2,0) | ... R18: =VLOOKUP(R17,$O$3:$P$6,2,0)
B19: Annual Travel Distance (km) | J19: 340 | K19: 1300 | L19: 28590 | M19: 16920 | N19: 1100 | O19: 9777.6 | P19: 39304 | S19: {=SUMPRODUCT(C18:R18,C19:R19,'Cat 1'!C17:R17/1000)} | T19: =S19/1000
A20: Gyeongju | B20: Transport Mode | C20: Truck | D20: Truck | E20: Truck | F20: Air | G20: Truck | H20: Truck | I20: Truck | J20: Truck | K20: Truck | L20: Truck | M20: Truck | N20: Truck | O20: Truck | P20: Truck | Q20: Truck | R20: Truck
B21: Emission Factor (Auto) | C21: =VLOOKUP(C20,$O$3:$P$6,2,0) | D21: =VLOOKUP(D20,$O$3:$P$6,2,0) | E21: =VLOOKUP(E20,$O$3:$P$6,2,0) | F21: =VLOOKUP(F20,$O$3:$P$6,2,0) | G21: =VLOOKUP(G20,$O$3:$P$6,2,0) | H21: =VLOOKUP(H20,$O$3:$P$6,2,0) | I21: =VLOOKUP(I20,$O$3:$P$6,2,0) | J21: =VLOOKUP(J20,$O$3:$P$6,2,0) | ... R21: =VLOOKUP(R20,$O$3:$P$6,2,0)
B22: Annual Travel Distance (km) | I22: 528 | J22: 1200 | K22: 1440 | L22: 120 | M22: 336 | N22: 16560 | O22: 1200 | P22: 24720 | S22: {=SUMPRODUCT(C21:R21,C22:R22,'Cat 1'!C19:R19/1000)} | T22: =S22/1000
A23: Asan | B23: Transport Mode | C23: Truck | D23: Truck | E23: Truck | F23: Air | G23: Truck | H23: Truck | I23: Truck | J23: Truck | K23: Truck | L23: Truck | M23: Truck | N23: Truck | O23: Truck | P23: Truck | Q23: Truck | R23: Truck
B24: Emission Factor (Auto) | C24: =VLOOKUP(C23,$O$3:$P$6,2,0) | D24: =VLOOKUP(D23,$O$3:$P$6,2,0) | E24: =VLOOKUP(E23,$O$3:$P$6,2,0) | F24: =VLOOKUP(F23,$O$3:$P$6,2,0) | G24: =VLOOKUP(G23,$O$3:$P$6,2,0) | H24: =VLOOKUP(H23,$O$3:$P$6,2,0) | I24: =VLOOKUP(I23,$O$3:$P$6,2,0) | J24: =VLOOKUP(J23,$O$3:$P$6,2,0) | ... R24: =VLOOKUP(R23,$O$3:$P$6,2,0)
B25: Annual Travel Distance (km) | G25: 106 | I25: 14304 | J25: 40224 | K25: 24000 | L25: 34710.2 | M25: 21521.4 | N25: 3114.8 | O25: 12214 | P25: 21348.75 | Q25: 10107 | R25: 25211.1 | S25: {=SUMPRODUCT(C24:R24,C25:R25,'Cat 1'!C21:R21/1000)} | T25: =S25/1000
A26: Gwangju | B26: Transport Mode | C26: Truck | D26: Truck | E26: Truck | F26: Air | G26: Truck | H26: Truck | I26: Truck | J26: Truck | K26: Truck | L26: Truck | M26: Truck | N26: Truck | O26: Truck | P26: Truck | Q26: Truck | R26: Truck
B27: Emission Factor (Auto) | C27: =VLOOKUP(C26,$O$3:$P$6,2,0) | D27: =VLOOKUP(D26,$O$3:$P$6,2,0) | E27: =VLOOKUP(E26,$O$3:$P$6,2,0) | F27: =VLOOKUP(F26,$O$3:$P$6,2,0) | G27: =VLOOKUP(G26,$O$3:$P$6,2,0) | H27: =VLOOKUP(H26,$O$3:$P$6,2,0) | I27: =VLOOKUP(I26,$O$3:$P$6,2,0) | J27: =VLOOKUP(J26,$O$3:$P$6,2,0) | ... R27: =VLOOKUP(R26,$O$3:$P$6,2,0)
B28: Annual Travel Distance (km) | G28: 3840 | I28: 3840 | J28: 1053 | K28: 5280 | L28: 2295 | M28: 2160 | N28: 540 | O28: 28485 | P28: 55890 | Q28: 10491.429 | R28: 1728 | S28: {=SUMPRODUCT(C27:R27,C28:R28,'Cat 1'!C23:R23/1000)} | T28: =S28/1000
A29: Youngin | B29: Transport Mode | C29: Truck | D29: Truck | E29: Truck | F29: Air | G29: Truck | H29: Truck | I29: Truck | J29: Truck | K29: Truck | L29: Truck | M29: Truck | N29: Truck | O29: Truck | P29: Truck | Q29: Truck | R29: Truck
B30: Emission Factor (Auto) | C30: =VLOOKUP(C29,$O$3:$P$6,2,0) | D30: =VLOOKUP(D29,$O$3:$P$6,2,0) | E30: =VLOOKUP(E29,$O$3:$P$6,2,0) | F30: =VLOOKUP(F29,$O$3:$P$6,2,0) | G30: =VLOOKUP(G29,$O$3:$P$6,2,0) | H30: =VLOOKUP(H29,$O$3:$P$6,2,0) | I30: =VLOOKUP(I29,$O$3:$P$6,2,0) | J30: =VLOOKUP(J29,$O$3:$P$6,2,0) | ... R30: =VLOOKUP(R29,$O$3:$P$6,2,0)
B31: Annual Travel Distance (km) | C31: 1146.7 | D31: 1215 | E31: 2448 | I31: 7800 | J31: 3107 | K31: 16896 | L31: 6996 | M31: 1452 | N31: 9976 | O31: 10976 | P31: 1885 | S31: {=SUMPRODUCT(C30:R30,C31:R31,'Cat 1'!C25:R25/1000)} | T31: =S31/1000
A32: Beijing | B32: Transport Mode | C32: Truck | D32: Truck | E32: Truck | F32: Air | G32: Truck | H32: Truck | I32: Truck | J32: Truck | K32: Truck | L32: Truck | M32: Truck | N32: Truck | O32: Truck | P32: Truck | Q32: Truck | R32: Truck
B33: Emission Factor (Auto) | C33: =VLOOKUP(C32,$O$3:$P$6,2,0) | D33: =VLOOKUP(D32,$O$3:$P$6,2,0) | E33: =VLOOKUP(E32,$O$3:$P$6,2,0) | F33: =VLOOKUP(F32,$O$3:$P$6,2,0) | G33: =VLOOKUP(G32,$O$3:$P$6,2,0) | H33: =VLOOKUP(H32,$O$3:$P$6,2,0) | I33: =VLOOKUP(I32,$O$3:$P$6,2,0) | J33: =VLOOKUP(J32,$O$3:$P$6,2,0) | ... R33: =VLOOKUP(R32,$O$3:$P$6,2,0)
B34: Annual Travel Distance (km) | C34: 9540 | D34: 6360 | E34: 26040 | G34: 15 | H34: 3600 | I34: 1050 | J34: 6000 | K34: 16800 | L34: 96000 | M34: 45600 | N34: 201600 | O34: 2880 | P34: 7200 | Q34: 43200 | R34: 600 | S34: {=SUMPRODUCT(C33:R33,C34:R34,'Cat 1'!C27:R27/1000)} | T34: =S34/1000
A35: Yancheng | B35: Transport Mode | C35: Rail | D35: Truck | E35: Truck | F35: Air | G35: Truck | H35: Truck | I35: Truck | J35: Truck | K35: Truck | L35: Truck | M35: Truck | N35: Truck | O35: Truck | P35: Truck | Q35: Truck | R35: Truck
B36: Emission Factor (Auto) | C36: =VLOOKUP(C35,$O$3:$P$6,2,0) | D36: =VLOOKUP(D35,$O$3:$P$6,2,0) | E36: =VLOOKUP(E35,$O$3:$P$6,2,0) | F36: =VLOOKUP(F35,$O$3:$P$6,2,0) | G36: =VLOOKUP(G35,$O$3:$P$6,2,0) | H36: =VLOOKUP(H35,$O$3:$P$6,2,0) | I36: =VLOOKUP(I35,$O$3:$P$6,2,0) | J36: =VLOOKUP(J35,$O$3:$P$6,2,0) | ... R36: =VLOOKUP(R35,$O$3:$P$6,2,0)
B37: Annual Travel Distance (km) | D37: 17576.4 | E37: 14013.6 | I37: 4320 | J37: 7956 | K37: 5553.6 | L37: 8838 | M37: 504 | N37: 782.4 | S37: {=SUMPRODUCT(C36:R36,C37:R37,'Cat 1'!C29:R29/1000)} | T37: =S37/1000
A38: Mannur | B38: Transport Mode | C38: Truck | D38: Truck | E38: Truck | F38: Truck | G38: Truck | H38: Truck | I38: Truck | J38: Truck | K38: Truck | L38: Ocean Vessel | M38: Truck | N38: Truck | O38: Truck | P38: Truck | Q38: Truck | R38: Truck
B39: Emission Factor (Auto) | C39: =VLOOKUP(C38,$O$3:$P$6,2,0) | D39: =VLOOKUP(D38,$O$3:$P$6,2,0) | E39: =VLOOKUP(E38,$O$3:$P$6,2,0) | F39: =VLOOKUP(F38,$O$3:$P$6,2,0) | G39: =VLOOKUP(G38,$O$3:$P$6,2,0) | H39: =VLOOKUP(H38,$O$3:$P$6,2,0) | I39: =VLOOKUP(I38,$O$3:$P$6,2,0) | J39: =VLOOKUP(J38,$O$3:$P$6,2,0) | ... R39: =VLOOKUP(R38,$O$3:$P$6,2,0)
B40: Annual Travel Distance (km) | C40: 40111.404 | E40: 31345.775 | F40: 316.28898 | S40: {=SUMPRODUCT(C39:R39,C40:R40,'Cat 1'!C31:R31/1000)} | T40: =S40/1000
A41: Orgadam | B41: Transport Mode | C41: Truck | D41: Truck | E41: Truck | F41: Truck | G41: Truck | H41: Truck | I41: Truck | J41: Truck | K41: Truck | L41: Ocean Vessel | M41: Truck | N41: Truck | O41: Truck | P41: Truck | Q41: Truck | R41: Truck
...

Sheet Cat 5
A1: ◆ SCOPE 3 Carbon Emissions – Cat 5. Waste Generated in Operations
A3: ※ Collection period: 2025 Jan 1 – Dec 31 | F3: ※ Scope 3 Cat 5 Total Emissions | K3: Classification | L3: Emission Factor
A4: ※ Note: Enter annual total waste tonnage in column B → Light green cells | F4: =I34 | K4: Landfill | L4: 455.1
A5: Enter ratios separately for landfill ~ wastewater treatment → Blue cells | K5: Incineration | L5: 1182
A6: Total ratio must be confirmed at 100% | K6: Recycling | L6: 0
K7: Wastewater Treatment | L7: 30
A9: By subsidiary | B9: Annual Total Waste (tonnes) | C9: By subsidiary | D9: Landfill | E9: Incineration | F9: Recycling | G9: Wastewater Treatment | H9: Emissions (kgCO2eq) | I9: Emissions (tCO2eq) | K9: Total Ratio Sum
A10: ex) | B10: 40 | C10: Ratio | D10: 0.25 | E10: 0.05 | F10: 0.6 | G10: 0.1
C11: Emission Factor (Auto) | D11: =VLOOKUP(D9,$K$4:$L$7,2,0) | E11: =VLOOKUP(E9,$K$4:$L$7,2,0) | F11: =VLOOKUP(F9,$K$4:$L$7,2,0) | G11: =VLOOKUP(G9,$K$4:$L$7,2,0) | H11: =SUMPRODUCT(D10:F10,D11:F11)*B10 | I11: =H11/1000
A12: Dongtan | B12: 13.5 | C12: Ratio | D12: 0 | E12: 0.2 | F12: 0.8 | G12: 0 | H12: =SUMPRODUCT($D$11:$G$11,D12:G12)*B12 | I12: =H12/1000 | K12: =SUM(D12:G12)
A13: Logistics Center | B13: 16.2 | C13: Ratio | D13: 0 | E13: 0.1 | F13: 0.9 | G13: 0 | H13: =SUMPRODUCT($D$11:$G$11,D13:G13)*B13 | I13: =H13/1000 | K13: =SUM(D13:G13)
A14: Gyeongju | B14: 69.551 | C14: Ratio | D14: 0 | E14: 1 | F14: 0 | G14: 0 | H14: =SUMPRODUCT($D$11:$G$11,D14:G14)*B14 | I14: =H14/1000 | K14: =SUM(D14:G14)
A15: Asan | B15: 57.91 | C15: Ratio | D15: 0 | E15: 1 | F15: 0 | G15: 0 | H15: =SUMPRODUCT($D$11:$G$11,D15:G15)*B15 | I15: =H15/1000 | K15: =SUM(D15:G15)
A16: Gwangju | B16: 26.73 | C16: Ratio | D16: 0.6 | E16: 0 | F16: 0.4 | G16: 0 | H16: =SUMPRODUCT($D$11:$G$11,D16:G16)*B16 | I16: =H16/1000 | K16: =SUM(D16:G16)
A17: Youngin | B17: 29.47 | C17: Ratio | D17: 0 | E17: 1 | F17: 0 | G17: 0 | H17: =SUMPRODUCT($D$11:$G$11,D17:G17)*B17 | I17: =H17/1000 | K17: =SUM(D17:G17)
A18: Beijing | C18: Ratio | D18: 0 | E18: 0 | F18: 0 | G18: 0 | H18: =SUMPRODUCT($D$11:$G$11,D18:G18)*B18 | I18: =H18/1000 | K18: =SUM(D18:G18)
A19: Yancheng | B19: 13.9 | C19: Ratio | D19: 0 | E19: 0.49 | F19: 0.51 | G19: 0 | H19: =SUMPRODUCT($D$11:$G$11,D19:G19)*B19 | I19: =H19/1000 | K19: =SUM(D19:G19)
A20: Mannur | B20: =14464*49% | C20: Ratio | D20: 0.49 | E20: 0 | F20: 0 | G20: 0 | H20: =SUMPRODUCT($D$11:$G$11,D20:G20)*B20 | I20: =H20/1000 | K20: =SUM(D20:G20)
A21: Orgadam | B21: =7996*25% | C21: Ratio | D21: 0.25 | E21: 0 | F21: 0 | G21: 0 | H21: =SUMPRODUCT($D$11:$G$11,D21:G21)*B21 | I21: =H21/1000 | K21: =SUM(D21:G21)
A22: Bangalore | C22: Ratio | D22: 0 | E22: 0 | F22: 0 | G22: 0 | H22: =SUMPRODUCT($D$11:$G$11,D22:G22)*B22 | I22: =H22/1000 | K22: =SUM(D22:G22)
A23: Pune | B23: =5280*35% | C23: Ratio | D23: 0.35 | E23: 0 | F23: 0 | G23: 0 | H23: =SUMPRODUCT($D$11:$G$11,D23:G23)*B23 | I23: =H23/1000 | K23: =SUM(D23:G23)
A24: Trzyniec | C24: Ratio | D24: 0 | E24: 0 | F24: 0 | G24: 0 | H24: =SUMPRODUCT($D$11:$G$11,D24:G24)*B24 | I24: =H24/1000 | K24: =SUM(D24:G24)
A25: Žilina | C25: Ratio | D25: 0 | E25: 0 | F25: 0 | G25: 0 | H25: =SUMPRODUCT($D$11:$G$11,D25:G25)*B25 | I25: =H25/1000 | K25: =SUM(D25:G25)
A26: Bystřice | B26: 82.322 | C26: Ratio | D26: 0.45 | E26: 0 | F26: 0.55 | G26: 0 | H26: =SUMPRODUCT($D$11:$G$11,D26:G26)*B26 | I26: =H26/1000 | K26: =SUM(D26:G26)
A27: Lipovice | C27: Ratio | D27: 0 | E27: 0 | F27: 0 | G27: 0 | H27: =SUMPRODUCT($D$11:$G$11,D27:G27)*B27 | I27: =H27/1000 | K27: =SUM(D27:G27)
A28: Mikulov | B28: =233.56*92% | C28: Ratio | D28: 0.92 | E28: 0 | F28: 0 | G28: 0 | H28: =SUMPRODUCT($D$11:$G$11,D28:G28)*B28 | I28: =H28/1000 | K28: =SUM(D28:G28)
A29: İzmit | C29: Ratio | D29: 0 | E29: 0 | F29: 0 | G29: 0 | H29: =SUMPRODUCT($D$11:$G$11,D29:G29)*B29 | I29: =H29/1000 | K29: =SUM(D29:G29)
A30: Bekasi | B30: 173 | C30: Ratio | D30: 0.31 | E30: 0.31 | F30: 0.38 | G30: 0 | H30: =SUMPRODUCT($D$11:$G$11,D30:G30)*B30 | I30: =H30/1000 | K30: =SUM(D30:G30)
A31: Indiana | B31: 710.16 | C31: Ratio | D31: 0.5753 | E31: 0 | F31: 0.4247 | G31: 0 | H31: =SUMPRODUCT($D$11:$G$11,D31:G31)*B31 | I31: =H31/1000 | K31: =SUM(D31:G31)
A32: Alabama | B32: 1561.94 | C32: Ratio | D32: 0.19200481 | E32: 0 | F32: 0.80799519 | G32: 0 | H32: =SUMPRODUCT($D$11:$G$11,D32:G32)*B32 | I32: =H32/1000 | K32: =SUM(D32:G32)
A33: Savannah | B33: 150 | C33: Ratio | D33: 1 | E33: 0 | F33: 0 | G33: 0 | H33: =SUMPRODUCT($D$11:$G$11,D33:G33)*B33 | I33: =H33/1000 | K33: =SUM(D33:G33)
A34: Total | D34: =SUM(D12:D33) | E34: =SUM(E12:E33) | F34: =SUM(F12:F33) | G34: =SUM(G12:G33) | H34: =SUM(H12:H33) | I34: =SUM(I12:I33)

Sheet Cat 6.7
A1: ◆ SCOPE 3 Carbon Emissions – Cat 6. Business Travel & Cat 7. Employee Commuting
A3: ※ Collection period: 2025 Jan 1 – Dec 31 | F3: ※ Scope 3 Cat 6 Total Emissions | H3: ※ Scope 3 Cat 7 Total Emissions
A4: ※ Note: Enter annual total distance in km only → Blue cells | F4: =J35 | H4: =R35
A5: Travel distance based on round trip
C8: ▼ Internal System | D8: ▼ Internal System | E8: ▼ Internal System | F8: ▼ Internal System | G8: ▼ Internal System | H8: ▼ Travel Agency | K8: ▼ Survey | L8: ▼ Survey | M8: ▼ Survey | N8: ▼ Survey | O8: ▼ Survey | P8: ▼ Subsidiary Management Team
C9: Business Travel | K9: Employee Commuting
A10: By subsidiary | B10: Classification | C10: Private Vehicle | D10: KTX/SRT | E10: Regular Train | F10: Bus | G10: Subway / Metro | H10: Air | I10: Emissions (kgCO2eq) | J10: Emissions (tCO2eq) | K10: Private Vehicle | L10: KTX/SRT | M10: Regular Train | N10: Bus | O10: Subway / Metro | P10: Commuter Bus | Q10: Emissions (kgCO2eq) | R10: Emissions (tCO2eq)
A11: Emission Factor (Do Not Modify) | C11: 0.21 | D11: 0.03 | E11: 0.02 | F11: 0.0277 | G11: 0.00153 | H11: 0.15 | K11: 0.21 | L11: 0.03 | M11: 0.02 | N11: 0.0277 | O11: 0.00153 | P11: 0.0277
A12: ex) | B12: Travel Distance (Round Trip) | C12: 2000 | D12: 5000 | E12: 0 | F12: 0 | G12: 0 | H12: 60000 | I12: =SUMPRODUCT($C$11:$H$11,C12:H12) | J12: =I12/1000 | K12: 20000 | L12: 500 | M12: 0 | N12: 250 | O12: 350 | P12: 2500 | Q12: =SUMPRODUCT($K$11:$P$11,K12:P12) | R12: =Q12/1000
A13: Dongtan | B13: Travel Distance (Round Trip) | C13: 165827.1 | D13: 65783.6 | E13: 542 | F13: 5067.6 | G13: 162.6 | H13: 3577812 | I13: =SUMPRODUCT($C$11:$H$11,C13:H13) | J13: =I13/1000 | K13: 647849.9 | L13: 55084 | M13: 0 | N13: 10422.8 | O13: 54 | P13: 0 | Q13: =SUMPRODUCT($K$11:$P$11,K13:P13) | R13: =Q13/1000
A14: Logistics Center | B14: Travel Distance (Round Trip) | C14: 1413 | I14: =SUMPRODUCT($C$11:$H$11,C14:H14) | J14: =I14/1000 | K14: 39330 | L14: 0 | M14: 0 | N14: 0 | O14: 0 | P14: 34500 | Q14: =SUMPRODUCT($K$11:$P$11,K14:P14) | R14: =Q14/1000
A15: Gyeongju | B15: Travel Distance (Round Trip) | C15: 103760 | I15: =SUMPRODUCT($C$11:$H$11,C15:H15) | J15: =I15/1000 | P15: 221589 | Q15: =SUMPRODUCT($K$11:$P$11,K15:P15) | R15: =Q15/1000
A16: Asan | B16: Travel Distance (Round Trip) | C16: 287325 | I16: =SUMPRODUCT($C$11:$H$11,C16:H16) | J16: =I16/1000 | K16: 284280 | Q16: =SUMPRODUCT($K$11:$P$11,K16:P16) | R16: =Q16/1000
A17: Gwangju | B17: Travel Distance (Round Trip) | C17: 29026.8 | D17: 3810 | I17: =SUMPRODUCT($C$11:$H$11,C17:H17) | J17: =I17/1000 | K17: 255384 | P17: 44352 | Q17: =SUMPRODUCT($K$11:$P$11,K17:P17) | R17: =Q17/1000
A18: Youngin | B18: Travel Distance (Round Trip) | C18: 5925 | D18: 2284 | I18: =SUMPRODUCT($C$11:$H$11,C18:H18) | J18: =I18/1000 | K18: 131508 | P18: 39312 | Q18: =SUMPRODUCT($K$11:$P$11,K18:P18) | R18: =Q18/1000
A19: Beijing | B19: Travel Distance (Round Trip) | C19: 79800 | I19: =SUMPRODUCT($C$11:$H$11,C19:H19) | J19: =I19/1000 | Q19: =SUMPRODUCT($K$11:$P$11,K19:P19) | R19: =Q19/1000
A20: Yancheng | B20: Travel Distance (Round Trip) | I20: =SUMPRODUCT($C$11:$H$11,C20:H20) | J20: =I20/1000 | K20: 432000 | Q20: =SUMPRODUCT($K$11:$P$11,K20:P20) | R20: =Q20/1000
A21: Mannur | B21: Travel Distance (Round Trip) | I21: =SUMPRODUCT($C$11:$H$11,C21:H21) | J21: =I21/1000 | K21: 185188 | P21: 675457 | Q21: =SUMPRODUCT($K$11:$P$11,K21:P21) | R21: =Q21/1000
A22: Orgadam | B22: Travel Distance (Round Trip) | I22: =SUMPRODUCT($C$11:$H$11,C22:H22) | J22: =I22/1000 | K22: 3000 | P22: 702253 | Q22: =SUMPRODUCT($K$11:$P$11,K22:P22) | R22: =Q22/1000
A23: Bangalore | B23: Travel Distance (Round Trip) | C23: 33710 | F23: 48829 | I23: =SUMPRODUCT($C$11:$H$11,C23:H23) | J23: =I23/1000 | Q23: =SUMPRODUCT($K$11:$P$11,K23:P23) | R23: =Q23/1000
A24: Pune | B24: Travel Distance (Round Trip) | I24: =SUMPRODUCT($C$11:$H$11,C24:H24) | J24: =I24/1000 | K24: 110633 | P24: 59076 | Q24: =SUMPRODUCT($K$11:$P$11,K24:P24) | R24: =Q24/1000
A25: Trzyniec | B25: Travel Distance (Round Trip) | I25: =SUMPRODUCT($C$11:$H$11,C25:H25) | J25: =I25/1000 | Q25: =SUMPRODUCT($K$11:$P$11,K25:P25) | R25: =Q25/1000
A26: Žilina | B26: Travel Distance (Round Trip) | I26: =SUMPRODUCT($C$11:$H$11,C26:H26) | J26: =I26/1000 | Q26: =SUMPRODUCT($K$11:$P$11,K26:P26) | R26: =Q26/1000
A27: Bystřice | B27: Travel Distance (Round Trip) | I27: =SUMPRODUCT($C$11:$H$11,C27:H27) | J27: =I27/1000 | K27: 136244 | N27: 22848 | P27: 501704 | Q27: =SUMPRODUCT($K$11:$P$11,K27:P27) | R27: =Q27/1000
A28: Lipovice | B28: Travel Distance (Round Trip) | I28: =SUMPRODUCT($C$11:$H$11,C28:H28) | J28: =I28/1000 | K28: 1704 | Q28: =SUMPRODUCT($K$11:$P$11,K28:P28) | R28: =Q28/1000
A29: Mikulov | B29: Travel Distance (Round Trip) | C29: 143659 | F29: 8228 | I29: =SUMPRODUCT($C$11:$H$11,C29:H29) | J29: =I29/1000 | Q29: =SUMPRODUCT($K$11:$P$11,K29:P29) | R29: =Q29/1000
A30: İzmit | B30: Travel Distance (Round Trip) | I30: =SUMPRODUCT($C$11:$H$11,C30:H30) | J30: =I30/1000 | Q30: =SUMPRODUCT($K$11:$P$11,K30:P30) | R30: =Q30/1000
A31: Bekasi | B31: Travel Distance (Round Trip) | C31: 3722.4 | I31: =SUMPRODUCT($C$11:$H$11,C31:H31) | J31: =I31/1000 | K31: 108314.8 | Q31: =SUMPRODUCT($K$11:$P$11,K31:P31) | R31: =Q31/1000
A32: Indiana | B32: Travel Distance (Round Trip) | C32: 14434 | H32: 1764 | I32: =SUMPRODUCT($C$11:$H$11,C32:H32) | J32: =I32/1000 | K32: 39121 | Q32: =SUMPRODUCT($K$11:$P$11,K32:P32) | R32: =Q32/1000
A33: Alabama | B33: Travel Distance (Round Trip) | C33: 240740 | H33: 126258 | I33: =SUMPRODUCT($C$11:$H$11,C33:H33) | J33: =I33/1000 | Q33: =SUMPRODUCT($K$11:$P$11,K33:P33) | R33: =Q33/1000
A34: Savannah | B34: Travel Distance (Round Trip) | C34: 1555 | H34: 4184 | I34: =SUMPRODUCT($C$11:$H$11,C34:H34) | J34: =I34/1000 | K34: 115544 | Q34: =SUMPRODUCT($K$11:$P$11,K34:P34) | R34: =Q34/1000
A35: Total | C35: =SUM(C13:C34) | D35: =SUM(D13:D34) | E35: =SUM(E13:E34) | F35: =SUM(F13:F34) | G35: =SUM(G13:G34) | H35: =SUM(H13:H34) | I35: =SUM(I13:I34) | J35: =SUM(J13:J34) | ... R35: =SUM(R13:R34)

Sheet Cat 9
A1: ◆ SCOPE 3 Carbon Emissions – Cat 9. Downstream Transportation and Distribution
Q2: Classification | R2: Emission Factor | BD2: Combined Transport | BE2: Combined Transport | BF2: Combined Transport | BG2: Combined Transport | BH2: Combined Transport | BI2: Combined Transport | BJ2: Combined Transport | BK2: Combined Transport | BL2: Combined Transport | BM2: Combined Transport | BN2: Combined Transport | BO2: Combined Transport | BP2: Combined Transport | BQ2: Select | BR2: Transport Distance
A3: ※ Collection period: 2025 Jan 1 – Dec 31 | F3: ※ Scope 3 Cat 9 Total Emissions | Q3: Truck | R3: 9.3e-05 | BD3: Air + Truck | BE3: Air + Truck | BF3: Air + Truck | BG3: Air + Truck | BH3: Air + Truck | BI3: Air + Truck | BJ3: Air + Truck | BK3: Air + Truck | BL3: Air + Truck | BM3: Air + Truck | BN3: Air + Truck | BO3: Air + Truck | BP3: Air + Truck | BQ3: Air | BR3: Air distance only
A4: ※ Note: Select transport mode from dropdown [based on primary transport mode] → Light green cells | F4: =BR103 | Q4: Rail | R4: 0.03507 | BD4: Rail + Truck | BE4: Rail + Truck | BF4: Rail + Truck | BG4: Rail + Truck | BH4: Rail + Truck | BI4: Rail + Truck | BJ4: Rail + Truck | BK4: Rail + Truck | BL4: Rail + Truck | BM4: Rail + Truck | BN4: Rail + Truck | BO4: Rail + Truck | BP4: Rail + Truck | BQ4: Rail | BR4: Rail distance only
A5: Annual travel distance: from subsidiary to customer delivery → Blue cells | Q5: Air | R5: 1 | BD5: Sea + Truck | BE5: Sea + Truck | BF5: Sea + Truck | BG5: Sea + Truck | BH5: Sea + Truck | BI5: Sea + Truck | BJ5: Sea + Truck | BK5: Sea + Truck | BL5: Sea + Truck | BM5: Sea + Truck | BN5: Sea + Truck | BO5: Sea + Truck | BP5: Sea + Truck | BQ5: Sea | BR5: Sea distance only
A6: Annual total distance (one-way basis) | Q6: Ocean Vessel | R6: 9.6e-06
A7: Total sold weight: weight per item × total delivery qty → Light pink cells | Q7: Ocean Vessel | R7: 9.6e-06
R9: If additional customers, specify and add to corresponding cells
A10: By subsidiary | B10: Classification | C10: HMC (Hyundai Direct Supply) | D10: Transys | E10: Adient | F10: Lear | G10: Mobis | H10: Daeyu Atech | I10: Daewon Precision | J10: DAS | K10: Seohyun Ihwa | L10: Geumchang | M10: Gwangmyeong | N10: NHK | O10: Magna | P10: Samsung SDI | Q10: TS-TECH | R10: Asan DAS | S10: Asan Adient Prototype Room | T10: AOCE | U10: NVH Korea | V10: ZF LIFETEC | W10: Gyeongju Daehan Packaging | X10: Nara M&D | Y10: Daedong Mobel | Z10: Dong-A Hwaseong | AA10: Duol Asan Plant | AB10: Duol Ulsan Plant | AC10: Mobis Mabuk R&D Center | AD10: Mobis Seosan Proving Ground | AE10: Mobis Uiwang R&D Center | AF10: Samwon Mould Precision | AG10: Seoyeon CNF | AH10: Seoyeon Ihwa Asan Plant | AI10: Seoyeon Industries | AJ10: Seoyeon Top Metal | AK10: Smart DNS | AL10: Shinsung FA | AM10: Shinchang FA | AN10: Atech Solution | AO10: Ian Enterprise | AP10: Zayd | AQ10: Taewung Tech | AR10: Praco | AS10: Korea Mold | AT10: Hanon Systems | AU10: Hanwha Advanced Materials Sejong Plant | AV10: Hyeonjin Globaltech | AW10: Hwaseong UMS | AX10: Daehan Packaging | AY10: Daeyu Atech (Asan) | AZ10: Dongwon Metal | BA10: DSC Logistics Center | BB10: DSC Asan | BC10: Okcheon Industry | BD10: MINDA | BE10: DSC (India Plant 4) | BF10: DSC (India Plant 1) | BG10: SPACK | BH10: Crown Tech | BI10: Jeongun | BJ10: DSC (India Plant 2) | BK10: SK1 | BL10: CZ DSC | BM10: CZ KMJ | BN10: SEJIN | BO10: AAA | BQ10: Emissions (kgCO2eq) | BR10: Emissions (tCO2eq)
A11: ex) | B11: Transport Mode | C11: Rail | D11: Truck | E11: Truck | F11: Air | G11: Truck | H11: Truck | I11: Truck | J11: Truck | K11: Truck | L11: Ocean Vessel | M11: Truck | N11: Truck | O11: Truck | P11: Truck | Q11: Truck | R11: Truck | S11: Truck | T11: Truck | U11: Truck | V11: Truck | W11: Truck | X11: Truck | Y11: Truck | Z11: Truck | AA11: Truck | AB11: Truck | AC11: Truck | AD11: Truck | AE11: Truck | AF11: Truck | AG11: Truck | AH11: Truck | AI11: Truck | AJ11: Truck | AK11: Truck | AL11: Truck | AM11: Truck | AN11: Truck | AO11: Truck | AP11: Truck | AQ11: Truck | AR11: Truck | AS11: Truck | AT11: Truck | AU11: Truck | AV11: Truck | AW11: Truck | AX11: Truck | AY11: Truck | AZ11: Truck | BA11: Truck | BB11: Truck | BC11: Truck | BD11: Truck | BE11: Truck | BF11: Truck | BG11: Truck | BH11: Truck | BI11: Truck | BJ11: Truck | BK11: Truck | BL11: Truck | BM11: Truck | BN11: Truck | BO11: Truck | BP11: Truck | BQ11: Truck
B12: Emission Factor (Auto) | C12: =VLOOKUP(C11,$Q$3:$R$6,2,0) | D12: =VLOOKUP(D11,$Q$3:$R$6,2,0) | E12: =VLOOKUP(E11,$Q$3:$R$6,2,0) | F12: =VLOOKUP(F11,$Q$3:$R$6,2,0) | G12: =VLOOKUP(G11,$Q$3:$R$6,2,0) | H12: =VLOOKUP(H11,$Q$3:$R$6,2,0) | I12: =VLOOKUP(I11,$Q$3:$R$6,2,0) | J12: =VLOOKUP(J11,$Q$3:$R$6,2,0) | ... BP12: =VLOOKUP(BP11,$Q$3:$R$6,2,0)
B13: Annual Travel Distance (km) | C13: 2000 | D13: 3000 | E13: 1000 | F13: 3000 | G13: 3000 | H13: 3000 | I13: 1000 | J13: 1000 | K13: 500 | L13: 500 | M13: 500 | N13: 2500 | O13: 500 | P13: 3500 | Q13: 3500
B14: Total Sold Weight (kg) | C14: 500 | D14: 300 | E14: 200 | F14: 200 | G14: 150 | H14: 50 | I14: 50 | J14: 60 | K14: 10 | L14: 10 | M14: 5 | N14: 50 | O14: 5 | P14: 150 | Q14: 50 | BQ14: {=SUMPRODUCT(C12:BP12,C13:BP13,C14:BP14/1000)} | BR14: =BQ14/1000
A15: Dongtan | B15: Transport Mode | C15: Truck | D15: Truck | E15: Truck | F15: Truck | G15: Truck | H15: Truck | I15: Truck | J15: Truck | K15: Truck | L15: Truck | M15: Truck | N15: Truck | O15: Truck | P15: Truck | Q15: Truck | R15: Truck | S15: Truck | T15: Truck | U15: Truck | V15: Truck | W15: Truck | X15: Truck | Y15: Truck | Z15: Truck | AA15: Truck | AB15: Truck | AC15: Truck | AD15: Truck | AE15: Truck | AF15: Truck | AG15: Truck | AH15: Truck | AI15: Truck | AJ15: Truck | AK15: Truck | AL15: Truck | AM15: Truck | AN15: Truck | AO15: Truck | AP15: Truck | AQ15: Truck | AR15: Truck | AS15: Truck | AT15: Truck | AU15: Truck | AV15: Truck | AW15: Truck | AX15: Truck | AY15: Truck | AZ15: Truck | BA15: Truck | BB15: Truck | BC15: Truck | BD15: Truck | BE15: Truck | BF15: Truck | BG15: Truck | BH15: Truck | BI15: Truck | BJ15: Truck | BK15: Truck | BL15: Truck | BM15: Truck | BN15: Truck | BO15: Truck | BP15: Truck
B16: Emission Factor (Auto) | C16: =VLOOKUP(C15,$Q$3:$R$6,2,0) | D16: =VLOOKUP(D15,$Q$3:$R$6,2,0) | E16: =VLOOKUP(E15,$Q$3:$R$6,2,0) | F16: =VLOOKUP(F15,$Q$3:$R$6,2,0) | G16: =VLOOKUP(G15,$Q$3:$R$6,2,0) | H16: =VLOOKUP(H15,$Q$3:$R$6,2,0) | I16: =VLOOKUP(I15,$Q$3:$R$6,2,0) | J16: =VLOOKUP(J15,$Q$3:$R$6,2,0) | ... BP16: =VLOOKUP(BP15,$Q$3:$R$6,2,0)
B17: Annual Travel Distance (km) | C17: 238 | D17: 682 | E17: 1598 | J17: 3399 | R17: 715 | S17: 118 | T17: 1898 | U17: 782 | V17: 74 | W17: 1252 | X17: 3575 | Y17: 94 | Z17: 339 | AA17: 134 | AB17: 324 | AC17: 144 | AD17: 114 | AE17: 32 | AF17: 48 | AG17: 903 | AH17: 64 | AI17: 594 | AJ17: 171 | AK17: 962 | AL17: 738 | AM17: 693 | AN17: 40 | AO17: 875 | AP17: 160 | AQ17: 341 | AR17: 54 | AS17: 2536 | AT17: 105 | AU17: 102 | AV17: 329 | AW17: 342
B18: Total Sold Weight (kg) | C18: 77.7542 | D18: 43052.97 | E18: 11250.043 | J18: 1871.9134 | R18: 5871.58 | S18: 107.8715 | T18: 2502.6283 | U18: 757.9614 | V18: 50.992 | W18: 3003.9154 | X18: 436.3644 | Y18: 82.2576 | Z18: 7.15 | AA18: 22.756 | AB18: 27.6206 | AC18: 152.0918 | AD18: 16.486 | AE18: 8.8194 | AF18: 12.086 | AG18: 198.3568 | AH18: 0.998 | AI18: 45.1238 | AJ18: 125.188 | AK18: 2958.8168 | AL18: 360.4915 | AM18: 813.5235 | AN18: 382.806 | AO18: 3160.53 | AP18: 133.2558 | AQ18: 17.0028 | AR18: 132.6 | AS18: 502.2798 | AT18: 8.243 | AU18: 0.998 | AV18: 164.369 | AW18: 6886.8568 | BQ18: {=SUMPRODUCT(C16:BP16,C17:BP17,C18:BP18/1000)} | BR18: =BQ18/1000
A19: Logistics Center | B19: Transport Mode | C19: Rail | D19: Truck | E19: Truck | F19: Air | G19: Truck | H19: Truck | I19: Truck | J19: Truck | K19: Truck | L19: Ocean Vessel | M19: Truck | N19: Truck | O19: Truck | P19: Truck | Q19: Truck | R19: Truck | S19: Truck | T19: Truck | U19: Truck | V19: Truck | W19: Truck | X19: Truck | Y19: Truck | Z19: Truck | AA19: Truck | AB19: Truck | AC19: Truck | AD19: Truck | AE19: Truck | AF19: Truck | AG19: Truck | AH19: Truck | AI19: Truck | AJ19: Truck | AK19: Truck | AL19: Truck | AM19: Truck | AN19: Truck | AO19: Truck | AP19: Truck | AQ19: Truck | AR19: Truck | AS19: Truck | AT19: Truck | AU19: Truck | AV19: Truck | AW19: Truck | AX19: Truck | AY19: Truck | AZ19: Truck | BA19: Truck | BB19: Truck | BC19: Truck | BD19: Truck | BE19: Truck | BF19: Truck | BG19: Truck | BH19: Truck | BI19: Truck | BJ19: Truck | BK19: Truck | BL19: Truck | BM19: Truck | BN19: Truck | BO19: Truck | BP19: Truck
B20: Emission Factor (Auto) | C20: =VLOOKUP(C19,$Q$3:$R$6,2,0) | D20: =VLOOKUP(D19,$Q$3:$R$6,2,0) | E20: =VLOOKUP(E19,$Q$3:$R$6,2,0) | F20: =VLOOKUP(F19,$Q$3:$R$6,2,0) | G20: =VLOOKUP(G19,$Q$3:$R$6,2,0) | H20: =VLOOKUP(H19,$Q$3:$R$6,2,0) | I20: =VLOOKUP(I19,$Q$3:$R$6,2,0) | J20: =VLOOKUP(J19,$Q$3:$R$6,2,0) | ... BP20: =VLOOKUP(BP19,$Q$3:$R$6,2,0)
B21: Annual Travel Distance (km)
B22: Total Sold Weight (kg) | BQ22: {=SUMPRODUCT(C20:BP20,C21:BP21,C22:BP22/1000)} | BR22: =BQ22/1000
A23: Gyeongju | B23: Transport Mode | C23: Rail | D23: Truck | E23: Truck | F23: Truck | G23: Truck | H23: Truck | I23: Truck | J23: Truck | K23: Truck | L23: Ocean Vessel | M23: Truck | N23: Truck | O23: Truck | P23: Truck | Q23: Truck | R23: Truck | S23: Truck | T23: Truck | U23: Truck | V23: Truck | W23: Truck | X23: Truck | Y23: Truck | Z23: Truck | AA23: Truck | AB23: Truck | AC23: Truck | AD23: Truck | AE23: Truck | AF23: Truck | AG23: Truck | AH23: Truck | AI23: Truck | AJ23: Truck | AK23: Truck | AL23: Truck | AM23: Truck | AN23: Truck | AO23: Truck | AP23: Truck | AQ23: Truck | AR23: Truck | AS23: Truck | AT23: Truck | AU23: Truck | AV23: Truck | AW23: Truck | AX23: Truck | AY23: Truck | AZ23: Truck | BA23: Truck | BB23: Truck | BC23: Truck | BD23: Truck | BE23: Truck | BF23: Truck | BG23: Truck | BH23: Truck | BI23: Truck | BJ23: Truck | BK23: Truck | BL23: Truck | BM23: Truck | BN23: Truck | BO23: Truck | BP23: Truck
B24: Emission Factor (Auto) | C24: =VLOOKUP(C23,$Q$3:$R$6,2,0) | D24: =VLOOKUP(D23,$Q$3:$R$6,2,0) | E24: =VLOOKUP(E23,$Q$3:$R$6,2,0) | F24: =VLOOKUP(F23,$Q$3:$R$6,2,0) | G24: =VLOOKUP(G23,$Q$3:$R$6,2,0) | H24: =VLOOKUP(H23,$Q$3:$R$6,2,0) | I24: =VLOOKUP(I23,$Q$3:$R$6,2,0) | J24: =VLOOKUP(J23,$Q$3:$R$6,2,0) | ... BP24: =VLOOKUP(BP23,$Q$3:$R$6,2,0)
B25: Annual Travel Distance (km) | C25: 129168 | F25: 299520 | J25: 11232 | AX25: 18720
B26: Total Sold Weight (kg) | C26: 4481568 | F26: 9008064 | J26: 898560 | AX26: 2096640 | BQ26: {=SUMPRODUCT(C24:BP24,C25:BP25,C26:BP26/1000)} | BR26: =BQ26/1000
A27: Asan | B27: Transport Mode | C27: Rail | D27: Truck | E27: Truck | F27: Air | G27: Truck | H27: Truck | I27: Truck | J27: Truck | K27: Truck | L27: Ocean Vessel | M27: Truck | N27: Truck | O27: Truck | P27: Truck | Q27: Truck | R27: Truck | S27: Truck | T27: Truck | U27: Truck | V27: Truck | W27: Truck | X27: Truck | Y27: Truck | Z27: Truck | AA27: Truck | AB27: Truck | AC27: Truck | AD27: Truck | AE27: Truck | AF27: Truck | AG27: Truck | AH27: Truck | AI27: Truck | AJ27: Truck | AK27: Truck | AL27: Truck | AM27: Truck | AN27: Truck | AO27: Truck | AP27: Truck | AQ27: Truck | AR27: Truck | AS27: Truck | AT27: Truck | AU27: Truck | AV27: Truck | AW27: Truck | AX27: Truck | AY27: Truck | AZ27: Truck | BA27: Truck | BB27: Truck | BC27: Truck | BD27: Truck | BE27: Truck | BF27: Truck | BG27: Truck | BH27: Truck | BI27: Truck | BJ27: Truck | BK27: Truck | BL27: Truck | BM27: Truck | BN27: Truck | BO27: Truck | BP27: Truck
B28: Emission Factor (Auto) | C28: =VLOOKUP(C27,$Q$3:$R$6,2,0) | D28: =VLOOKUP(D27,$Q$3:$R$6,2,0) | E28: =VLOOKUP(E27,$Q$3:$R$6,2,0) | F28: =VLOOKUP(F27,$Q$3:$R$6,2,0) | G28: =VLOOKUP(G27,$Q$3:$R$6,2,0) | H28: =VLOOKUP(H27,$Q$3:$R$6,2,0) | I28: =VLOOKUP(I27,$Q$3:$R$6,2,0) | J28: =VLOOKUP(J27,$Q$3:$R$6,2,0) | ... BP28: =VLOOKUP(BP27,$Q$3:$R$6,2,0)
B29: Annual Travel Distance (km) | C29: 792 | D29: 16416 | E29: 125712 | G29: 324 | H29: 5940 | J29: 9184 | M29: 741 | AY29: 2412
B30: Total Sold Weight (kg) | C30: 81360 | D30: 3778131 | E30: 9359448 | G30: 6937 | H30: 42381 | J30: 507518 | M30: 8114.4 | AY30: 46948 | BQ30: {=SUMPRODUCT(C28:BP28,C29:BP29,C30:BP30/1000)} | BR30: =BQ30/1000
A31: Gwangju | B31: Transport Mode | C31: Rail | D31: Truck | E31: Truck | F31: Air | G31: Truck | H31: Truck | I31: Truck | J31: Truck | K31: Truck | L31: Ocean Vessel | M31: Truck | N31: Truck | O31: Truck | P31: Truck | Q31: Truck | R31: Truck | S31: Truck | T31: Truck | U31: Truck | V31: Truck | W31: Truck | X31: Truck | Y31: Truck | Z31: Truck | AA31: Truck | AB31: Truck | AC31: Truck | AD31: Truck | AE31: Truck | AF31: Truck | AG31: Truck | AH31: Truck | AI31: Truck | AJ31: Truck | AK31: Truck | AL31: Truck | AM31: Truck | AN31: Truck | AO31: Truck | AP31: Truck | AQ31: Truck | AR31: Truck | AS31: Truck | AT31: Truck | AU31: Truck | AV31: Truck | AW31: Truck | AX31: Truck | AY31: Truck | AZ31: Truck | BA31: Truck | BB31: Truck | BC31: Truck | BD31: Truck | BE31: Truck | BF31: Truck | BG31: Truck | BH31: Truck | BI31: Truck | BJ31: Truck | BK31: Truck | BL31: Truck | BM31: Truck | BN31: Truck | BO31: Truck | BP31: Truck
B32: Emission Factor (Auto) | C32: =VLOOKUP(C31,$Q$3:$R$6,2,0) | D32: =VLOOKUP(D31,$Q$3:$R$6,2,0) | E32: =VLOOKUP(E31,$Q$3:$R$6,2,0) | F32: =VLOOKUP(F31,$Q$3:$R$6,2,0) | G32: =VLOOKUP(G31,$Q$3:$R$6,2,0) | H32: =VLOOKUP(H31,$Q$3:$R$6,2,0) | I32: =VLOOKUP(I31,$Q$3:$R$6,2,0) | J32: =VLOOKUP(J31,$Q$3:$R$6,2,0) | ... BP32: =VLOOKUP(BP31,$Q$3:$R$6,2,0)
B33: Annual Travel Distance (km) | H33: 173580 | P33: 9725
B34: Total Sold Weight (kg) | H34: 13745683 | P34: 499212 | BQ34: {=SUMPRODUCT(C32:BP32,C33:BP33,C34:BP34/1000)} | BR34: =BQ34/1000
A35: Youngin | B35: Transport Mode | C35: Rail | D35: Truck | E35: Truck | F35: Air | G35: Truck | H35: Truck | I35: Truck | J35: Truck | K35: Truck | L35: Ocean Vessel | M35: Truck | N35: Truck | O35: Truck | P35: Truck | Q35: Truck | R35: Truck | S35: Truck | T35: Truck | U35: Truck | V35: Truck | W35: Truck | X35: Truck | Y35: Truck | Z35: Truck | AA35: Truck | AB35: Truck | AC35: Truck | AD35: Truck | AE35: Truck | AF35: Truck | AG35: Truck | AH35: Truck | AI35: Truck | AJ35: Truck | AK35: Truck | AL35: Truck | AM35: Truck | AN35: Truck | AO35: Truck | AP35: Truck | AQ35: Truck | AR35: Truck | AS35: Truck | AT35: Truck | AU35: Truck | AV35: Truck | AW35: Truck | AX35: Truck | AY35: Truck | AZ35: Truck | BA35: Truck | BB35: Truck | BC35: Truck | BD35: Truck | BE35: Truck | BF35: Truck | BG35: Truck | BH35: Truck | BI35: Truck | BJ35: Truck | BK35: Truck | BL35: Truck | BM35: Truck | BN35: Truck | BO35: Truck | BP35: Truck
B36: Emission Factor (Auto) | C36: =VLOOKUP(C35,$Q$3:$R$6,2,0) | D36: =VLOOKUP(D35,$Q$3:$R$6,2,0) | E36: =VLOOKUP(E35,$Q$3:$R$6,2,0) | F36: =VLOOKUP(F35,$Q$3:$R$6,2,0) | G36: =VLOOKUP(G35,$Q$3:$R$6,2,0) | H36: =VLOOKUP(H35,$Q$3:$R$6,2,0) | I36: =VLOOKUP(I35,$Q$3:$R$6,2,0) | J36: =VLOOKUP(J35,$Q$3:$R$6,2,0) | ... BP36: =VLOOKUP(BP35,$Q$3:$R$6,2,0)
B37: Annual Travel Distance (km) | D37: 1911 | E37: 40712 | M37: 26325 | AZ37: 46410 | BA37: 33558 | BB37: 1344 | BC37: 1680
B38: Total Sold Weight (kg) | D38: 304154 | E38: 2175093 | M38: 268628 | AZ38: 390613 | BA38: 554240 | BB38: 97821 | BC38: 56782 | BQ38: {=SUMPRODUCT(C36:BP36,C37:BP37,C38:BP38/1000)} | BR38: =BQ38/1000
A39: Beijing | B39: Transport Mode | C39: Truck | D39: Truck | E39: Truck | F39: Air | G39: Truck | H39: Truck | I39: Truck | J39: Truck | K39: Truck | L39: Ocean Vessel | M39: Truck | N39: Truck | O39: Truck | P39: Truck | Q39: Truck | R39: Truck | S39: Truck | T39: Truck | U39: Truck | V39: Truck | W39: Truck | X39: Truck | Y39: Truck | Z39: Truck | AA39: Truck | AB39: Truck | AC39: Truck | AD39: Truck | AE39: Truck | AF39: Truck | AG39: Truck | AH39: Truck | AI39: Truck | AJ39: Truck | AK39: Truck | AL39: Truck | AM39: Truck | AN39: Truck | AO39: Truck | AP39: Truck | AQ39: Truck | AR39: Truck | AS39: Truck | AT39: Truck | AU39: Truck | AV39: Truck | AW39: Truck | AX39: Truck | AY39: Truck | AZ39: Truck | BA39: Truck | BB39: Truck | BC39: Truck | BD39: Truck | BE39: Truck | BF39: Truck | BG39: Truck | BH39: Truck | BI39: Truck | BJ39: Truck | BK39: Truck | BL39: Truck | BM39: Truck | BN39: Truck | BO39: Truck | BP39: Truck
B40: Emission Factor (Auto) | C40: =VLOOKUP(C39,$Q$3:$R$6,2,0) | D40: =VLOOKUP(D39,$Q$3:$R$6,2,0) | E40: =VLOOKUP(E39,$Q$3:$R$6,2,0) | F40: =VLOOKUP(F39,$Q$3:$R$6,2,0) | G40: =VLOOKUP(G39,$Q$3:$R$6,2,0) | H40: =VLOOKUP(H39,$Q$3:$R$6,2,0) | I40: =VLOOKUP(I39,$Q$3:$R$6,2,0) | J40: =VLOOKUP(J39,$Q$3:$R$6,2,0) | ... BP40: =VLOOKUP(BP39,$Q$3:$R$6,2,0)
B41: Annual Travel Distance (km) | C41: 600 | D41: 148212 | E41: 137058
...

Sheet SCOPE3 Calculation Basis
B1: ◆ SCOPE 3 Emissions Calculation Procedure
B3: SCOPE 3 Boundary | G3: STEP 1: Identify Calculation Categories | O3: STEP 2: Define Calculation Scope and Methodology
B5: Category | E5: Definition | G5: Scale | H5: Impact | I5: Risk | J5: Stakeholders | K5: Outsourcing | L5: Industry Guidance | M5: Revenue Analysis | O5: Calculation Method
B6: Up stream | C6: 1 | D6: Purchased Goods and Services | E6: GHG emissions from production of purchased goods/services (raw material extraction, manufacturing, etc.) | G6: Internal: steel sheet / wire / pipe / copper / lubricants, etc. External: finished goods purchased from supply chain Considered a significantly contributing activity to emissions | M6: Selected based on top 80% of supply chain (by revenue) | O6: Average Data Method
C7: 2 | D7: Capital Goods | E7: GHG emissions from producing purchased capital goods* * Capital goods: means of production (finished goods) used for manufacturing products, providing/selling/storing/transporting services | J7: Recognised as a material issue by customers and investors | O7: Average Data Method
C8: 3 | D8: Fuel and Energy-Related Activities | E8: GHG emissions from energy-related activities not included in Scope 1 and 2 | G8: Apply upstream emission factors based on third-party verified Scope 1 & 2 data – relatively clear, so completion is required | O8: Average Data Method
C9: 4 | D9: Upstream Transportation and Distribution | E9: GHG emissions from transportation and distribution related to purchased goods and services | H9: Activities with potential indirect emission reduction impact | O9: Distance-Based Method
C10: 5 | D10: Waste Generated in Operations | E10: GHG emissions from third-party treatment of waste generated at owned or operated facilities | J10: In accordance with civil society and government regulations | O10: Average Data Method
C11: 6 | D11: Business Travel | E11: GHG emissions from employee business travel using transportation owned or operated by third parties | H11: Target for potential emission reduction | O11: Distance-Based Method
C12: 7 | D12: Employee Commuting | E12: GHG emissions from transportation used by employees during commuting | H12: Target for potential emission reduction | O12: Distance-Based Method
C13: 8 | D13: Upstream Leased Assets | E13: GHG emissions from operation of assets leased from other companies | H13: Not Applicable | O13: Not Applicable
B14: Down stream | C14: 9 | D14: Downstream Transportation and Distribution | E14: GHG emissions from transportation and distribution of sold products/services | G14: Estimated to contribute significantly to emissions as delivery transportation is maintained for a wide variety of customers | O14: Distance-Based Method
C15: 10 | D15: Processing of Sold Products | E15: GHG emissions from processing of sold products by third-party companies that purchased them (Only calculated when selling intermediate goods/parts) | J15: Difficult to obtain information from customers | O15: Not Applicable
C16: 11 | D16: Use of Sold Products | E16: GHG emissions from use of sold products/services | J16: Difficult to obtain information from customers | O16: Not Applicable
C17: 12 | D17: End-of-Life Treatment of Sold Products | E17: GHG emissions from disposal of sold products | J17: Difficult to obtain information from customers | O17: Not Applicable
C18: 13 | D18: Downstream Leased Assets | E18: GHG emissions from operation of owned assets leased to other companies | H18: Not Applicable | O18: Not Applicable
C19: 14 | D19: Franchises | E19: Scope 1 & 2 emissions from franchise outlets (only calculated when operating a franchise business) | J19: Difficult to obtain information from customers | O19: Not Applicable
C20: 15 | D20: Investments | E20: Scope 1 & 2 emissions from investee companies | H20: Not Applicable | O20: Not Applicable

Sheet Calculation Reference Notes
