Workbook
Name _: #REF!
Name _: #REF!
Name _?: #N/A
Name _?_컛?___i: #REF!
Name _?_컛?___i: #REF!
Name _?쨲?f: #REF!
Name _?쨲?f: #REF!
Name __?: #REF!
Name __?: #REF!
Name __?_컛?___i: #REF!
Name __?_컛?___i: #REF!
Name __?쨲?f: #REF!
Name __?쨲?f: #REF!
Name ___?: #REF!
Name ___?: #REF!
Name ___?_컛?___i: #REF!
Name ___?_컛?___i: #REF!
Name ___?쨲?f: #REF!
Name ___?쨲?f: #REF!
Name ____?: #REF!
Name ____?: #REF!
Name ____?_컛?___i: #REF!
Name ____?_컛?___i: #REF!
Name ____?쨲?f: #REF!
Name ____?쨲?f: #REF!
Name _____?: #REF!
Name _____?: #REF!
Name _____?_컛?___i: #REF!
Name _____?_컛?___i: #REF!
Name _____?쨲?f: #REF!
Name _____?쨲?f: #REF!
Name ______?: #REF!
Name ______?: #REF!
Name ______?_컛?___i: #REF!
Name ______?_컛?___i: #REF!
Name ______?쨲?f: #REF!
Name ______?쨲?f: #REF!
Name _______?: #REF!
Name _______?: #REF!
Name _______?_컛?___i: #REF!
Name _______?_컛?___i: #REF!
Name _______?쨲?f: #REF!
Name _______?쨲?f: #REF!
Name ________?: #REF!
Name ________?: #REF!
Name ________?_컛?___i: #REF!
Name ________?_컛?___i: #REF!
Name ________?쨲?f: #REF!
Name ________?쨲?f: #REF!
Name _________?: #REF!
Name _________?: #REF!
Name _________?_컛?___i: #REF!
Name _________?_컛?___i: #REF!
Name _________?쨲?f: #REF!
Name _________?쨲?f: #REF!
Name __________?: #REF!
Name __________?: #REF!
Name __________a3: #REF!
Name __________a3: #REF!
Name _________a1: #REF!

Sheet 경영실적▶

Sheet 3.경영실적 PT
B1: ○ 2024년 만누르공장 손익실적 | F1: 해당월 입력(Month change) | G1: 3
P2: (단위 : 백만원, %)
B3: 계정 과목명 | C3: 2024년 계획 | E3: 2월 당월실적 | I3: 누계실적 | P3: 계획대비 분석
C4: 금액 | D4: % | E4: 계획 | F4: % | G4: 실적 | H4: % | I4: 계획 | J4: % | K4: 실적 | L4: % | M4: 차액 | N4: 차율 | O4: 실적율 | P4: 증감사유
B5: 매출액 | C5: =SUM(C6:C9) -> 104614.07 | D5: =C5/C$5 -> 1 | E5: =SUM(E6:E9) -> 9209.4917 | F5: =E5/E$5 -> 1 | G5: =SUM(G6:G9) -> 0 | H5: =G5/G$5 -> #DIV/0! | I5: =SUM(I6:I9) -> 26299.702 | J5: =I5/I$5 -> 1 | K5: =SUM(K6:K9) -> 17085.148 | L5: =K5/K$5 -> 1 | M5: =K5-I5 -> -9214.554 | N5: =L5-J5 -> 0 | O5: =K5/I5 -> 0.64963276 | P5: 계획 대비 실적 100% 달성
B6: 제품매출 | C6: =103134.64514176 -> 103134.65 | D6: =C6/C$5 -> 0.98585824 | E6: ='월계획 '!D81/1000 -> 9082.5158 | F6: =E6/E$5 -> 0.9862125 | G6: ='월계획 '!D113/1000 -> 0 | H6: =G6/G$5 -> #DIV/0! | I6: ='월계획 '!F81/1000 -> 25927.073 | J6: =I6/I$5 -> 0.98583144 | K6: ='월계획 '!F113/1000 -> 16477.453 | L6: =K6/K$5 -> 0.96443143 | M6: =K6-I6 -> -9449.6195 | N6: =L6-J6 -> -0.021400016 | O6: =K6/I6 -> 0.6355308 | P6: • AI3 17%(7.7억), BI3 7%(1억), QXI 6%(3.6억) 계획대비↑
B7: 상품매출 | C7: =1076.84561904 -> 1076.8456 | D7: =C7/C$5 -> 0.010293506 | E7: ='월계획 '!D82/1000 -> 92.084603 | F7: =E7/E$5 -> 0.00999888 | G7: ='월계획 '!D114/1000 -> 0 | H7: =G7/G$5 -> #DIV/0! | I7: ='월계획 '!F82/1000 -> 272.52022 | J7: =I7/I$5 -> 0.010362103 | K7: ='월계획 '!F114/1000 -> 479.81838 | L7: =K7/K$5 -> 0.028083947 | M7: =K7-I7 -> 207.29816 | N7: =L7-J7 -> 0.017721844 | O7: =K7/I7 -> 1.7606707 | P7: • BN7I -28%(3.3억), PS7 -34%(7억), SU2I -18%(3.4억)↓
B8: 기타매출 | C8: =741.192226300696 -> 741.19223 | D8: =C8/C$5 -> 0.0070850145 | E8: ='월계획 '!D83/1000 -> 65.151491 | F8: =E8/E$5 -> 0.0070743852 | G8: ='월계획 '!D115/1000 -> 0 | H8: =G8/G$5 -> #DIV/0! | I8: ='월계획 '!F83/1000 -> 186.64721 | J8: =I8/I$5 -> 0.0070969325 | K8: ='월계획 '!F115/1000 -> 127.87596 | L8: =K8/K$5 -> 0.0074846269 | M8: =K8-I8 -> -58.771252 | N8: =L8-J8 -> 0.00038769436 | O8: =K8/I8 -> 0.68512118
B9: CR | C9: =-338.610363153872 -> -338.61036 | D9: =C9/C$5 -> -0.0032367573 | E9: ='월계획 '!D84/1000 -> -30.260252 | F9: =E9/E$5 -> -0.0032857678 | G9: ='월계획 '!D116/1000 -> 0 | H9: =G9/G$5 -> #DIV/0! | I9: ='월계획 '!F84/1000 -> -86.538581 | J9: =I9/I$5 -> -0.0032904777 | K9: ='월계획 '!F116/1000 -> 0 | L9: =K9/K$5 -> 0 | M9: =K9-I9 -> 86.538581 | N9: =L9-J9 -> 0.0032904777 | O9: 0
B10: 판매원가 | C10: =C11+C14+C17 -> 97651.718 | D10: =C10/C$5 -> 0.93344725 | E10: =(E11+E14+E17) -> 8522.2503 | F10: =E10/E$5 -> 0.92537683 | G10: =G11+G14+G17 -> 0 | H10: =G10/G$5 -> #DIV/0! | I10: =I11+I14+I17 -> 24407.853 | J10: =I10/I$5 -> 0.92806578 | K10: =K11+K14+K17 -> 15963.992 | L10: =K10/K$5 -> 0.93437833 | M10: =M11+M14+M17 -> -8443.8613 | N10: =L10-J10 -> 0.0063125559 | O10: =K10/I10 -> 0.65405146
B11: 재료비 소계 | C11: =C12-C13 -> 84123.149 | D11: =C11/C$5 -> 0.80412842 | E11: =E12-E13 -> 7424.4875 | F11: =E11/E$5 -> 0.80617777 | G11: =G12-G13 -> 0 | H11: =G11/G$5 -> #DIV/0! | I11: =I12-I13 -> 21226.141 | J11: =I11/I$5 -> 0.80708676 | K11: =K12-K13 -> 13919.821 | L11: =K11/K$5 -> 0.81473227 | M11: =K11-I11 -> -7306.32 | N11: =L11-J11 -> 0.0076455029 | O11: =K11/I11 -> 0.6557867 | P11: 계획 대비 실적 재료비 0.7% ↑
B12: (재료비) | C12: 84123.149 | D12: =C12/C$5 -> 0.80412842 | E12: ='월계획 '!D87/1000 -> 7424.4875 | F12: =E12/E$5 -> 0.80617777 | G12: ='월계획 '!D119/1000 -> 0 | H12: =G12/G$5 -> #DIV/0! | I12: ='월계획 '!F87/1000 -> 21226.141 | J12: =I12/I$5 -> 0.80708676 | K12: ='월계획 '!F119/1000 -> 13883.384 | L12: =K12/K$5 -> 0.81259956 | M12: =K12-I12 -> -7342.7576 | N12: =L12-J12 -> 0.0055127996 | O12: =K12/I12 -> 0.65407007 | P12: • 리어 단가소급 (22년 M2EL 차종) 52백만 (0.30%) • 전년도 인보이스 (모비스) 51백만 (0.30%) • KD 환율변경 45백만 (0.26%) • 직구매 코일 가격 변동 -29백만 (-0.17%)
B13: (재고증감) | C13: 0 | D13: =C13/C$5 -> 0 | E13: ='월계획 '!D88/1000 -> 0 | F13: =E13/E$5 -> 0 | G13: ='월계획 '!D120/1000 -> 0 | H13: =G13/G$5 -> #DIV/0! | I13: ='월계획 '!F88/1000 -> 0 | J13: =I13/I$5 -> 0 | K13: ='월계획 '!F120/1000 -> -36.437552 | L13: =K13/K$5 -> -0.0021327034 | M13: =K13-I13 -> -36.437552 | N13: =L13-J13 -> -0.0021327034 | O13: 0
B14: 노무비 소계 | C14: =SUM(C15:C16) -> 4228.2977 | D14: =C14/C$5 -> 0.040418058 | E14: =SUM(E15:E16) -> 332.22012 | F14: =E14/E$5 -> 0.036073665 | G14: =SUM(G15:G16) -> 0 | H14: =G14/G$5 -> #DIV/0! | I14: =SUM(I15:I16) -> 973.40709 | J14: =I14/I$5 -> 0.037012096 | K14: =SUM(K15:K16) -> 641.47117 | L14: =K14/K$5 -> 0.037545544 | M14: =SUM(M15:M16) -> -331.93591 | N14: =L14-J14 -> 0.00053344845 | O14: =K14/I14 -> 0.65899579 | P14: 계획 대비 실적 0.0%
B15: (직접노무비) | C15: 2846.6259 | D15: =C15/C$5 -> 0.027210736 | E15: ='월계획 '!D90/1000 -> 222.21474 | F15: =E15/E$5 -> 0.024128882 | G15: ='월계획 '!D122/1000 -> 0 | H15: =G15/G$5 -> #DIV/0! | I15: ='월계획 '!F90/1000 -> 647.97444 | J15: =I15/I$5 -> 0.024638091 | K15: ='월계획 '!F122/1000 -> 424.69515 | L15: =K15/K$5 -> 0.024857564 | M15: =K15-I15 -> -223.27929 | N15: =L15-J15 -> 0.00021947294 | O15: =K15/I15 -> 0.6554196 | P15: • 직접직 0.01% ↑(계획 467, 실적 446명→21명↓), 휴일특근 ↑
B16: (간접노무비) | C16: 1381.6718 | D16: =C16/C$5 -> 0.013207322 | E16: ='월계획 '!D91/1000 -> 110.00538 | F16: =E16/E$5 -> 0.011944783 | G16: ='월계획 '!D123/1000 -> 0 | H16: =G16/G$5 -> #DIV/0! | I16: ='월계획 '!F91/1000 -> 325.43265 | J16: =I16/I$5 -> 0.012374005 | K16: ='월계획 '!F123/1000 -> 216.77602 | L16: =K16/K$5 -> 0.012687981 | M16: =K16-I16 -> -108.65662 | N16: =L16-J16 -> 0.00031397552 | O16: =K16/I16 -> 0.66611641 | P16: • 간접직 0.01% ↓(계획 93, 실적 97명→4명 ↑, 푸네지원)
B17: 경비 소계 | C17: =SUM(C18:C19) -> 9300.272 | D17: =C17/C$5 -> 0.088900774 | E17: =SUM(E18:E19) -> 765.54264 | F17: =E17/E$5 -> 0.083125396 | G17: =SUM(G18:G19) -> 0 | H17: =G17/G$5 -> #DIV/0! | I17: =SUM(I18:I19) -> 2208.3049 | J17: =I17/I$5 -> 0.083966918 | K17: =SUM(K18:K19) -> 1402.6996 | L17: =K17/K$5 -> 0.082100523 | M17: =SUM(M18:M19) -> -805.60534 | N17: =L17-J17 -> -0.0018663955 | O17: =K17/I17 -> 0.63519288 | P17: 계획 대비 실적 -0.2 %↓
B18: (감가상각비) | C18: 3532.9484 | D18: =C18/C$5 -> 0.033771254 | E18: ='월계획 '!D93/1000 -> 267.54299 | F18: =E18/E$5 -> 0.029050788 | G18: ='월계획 '!D125/1000 -> 0 | H18: =G18/G$5 -> #DIV/0! | I18: ='월계획 '!F93/1000 -> 763.02838 | J18: =I18/I$5 -> 0.029012815 | K18: ='월계획 '!F125/1000 -> 477.01773 | L18: =K18/K$5 -> 0.027920023 | M18: =K18-I18 -> -286.01065 | N18: =L18-J18 -> -0.0010927914 | O18: =K18/I18 -> 0.62516381 | P18: • 건물 수선비 33백만 ↑ └ KM 캐노피,정화조 10백만, 지붕보수 9백만, 기타 (도로,수도,식당) 14백만 • 복리후생 (체육대회연기, 식대등) 40백만 ↓
B19: (기타경비) | C19: 5767.3236 | D19: =C19/C$5 -> 0.05512952 | E19: ='월계획 '!D94/1000 -> 497.99965 | F19: =E19/E$5 -> 0.054074608 | G19: ='월계획 '!D126/1000 -> 0 | H19: =G19/G$5 -> #DIV/0! | I19: ='월계획 '!F94/1000 -> 1445.2765 | J19: =I19/I$5 -> 0.054954103 | K19: ='월계획 '!F126/1000 -> 925.68183 | L19: =K19/K$5 -> 0.054180499 | M19: =K19-I19 -> -519.59469 | N19: =L19-J19 -> -0.00077360404 | O19: =K19/I19 -> 0.6404877
B20: 영업이익 | C20: =C5-C10 -> 6962.3544 | D20: =C20/C$5 -> 0.066552752 | E20: =E5-E10 -> 687.24144 | F20: =E20/E$5 -> 0.074623167 | G20: =G5-G10 -> 0 | H20: =G20/G$5 -> #DIV/0! | I20: =I5-I10 -> 1891.8486 | J20: =I20/I$5 -> 0.071934223 | K20: =K5-K10 -> 1121.1559 | L20: =K20/K$5 -> 0.065621667 | M20: =M5-M10 -> -770.69274 | N20: =L20-J20 -> -0.0063125559 | O20: =-K20/I20 -> -0.59262452 | P20: * 영업이익 0.5% ↓
B21: 영업외수익 | C21: =SUM(C22:C23) -> 307.2 | D21: =C21/C$5 -> 0.0029365074 | E21: =SUM(E22:E23) -> 25.6 | F21: =E21/E$5 -> 0.0027797408 | G21: =SUM(G22:G23) -> 0 | H21: =G21/G$5 -> #DIV/0! | I21: =SUM(I22:I23) -> 76.8 | J21: =I21/I$5 -> 0.0029201852 | K21: =SUM(K22:K23) -> 197.20415 | L21: =K21/K$5 -> 0.011542432 | M21: =K21-I21 -> 120.40415 | N21: =L21-J21 -> 0.0086222466 | O21: =K21/I21 -> 2.5677624 | P21: 임대수익 0.5억, 외환차익 1억, 이자수익 0.2억
B22: (환차익) | D22: =C22/C$5 -> 0 | E22: ='월계획 '!D97/1000 -> 0 | F22: =E22/E$5 -> 0 | G22: ='월계획 '!D129/1000 -> 0 | H22: =G22/G$5 -> #DIV/0! | I22: ='월계획 '!F97/1000 -> 0 | J22: =I22/I$5 -> 0 | K22: ='월계획 '!F129/1000 -> 114.0296 | L22: =K22/K$5 -> 0.0066741946 | M22: =K22-I22 -> 114.0296 | N22: =L22-J22 -> 0.0066741946 | O22: =IF(K22<=1000,0,K22/I22) -> 0
B23: (환차익외) | C23: 307.2 | D23: =C23/C$5 -> 0.0029365074 | E23: =SUM('월계획 '!D98:D100)/1000 -> 25.6 | F23: =E23/E$5 -> 0.0027797408 | G23: =SUM('월계획 '!D130:D132)/1000 -> 0 | H23: =G23/G$5 -> #DIV/0! | I23: =SUM('월계획 '!F98:F100)/1000 -> 76.8 | J23: =I23/I$5 -> 0.0029201852 | K23: =SUM('월계획 '!F130:F132)/1000 -> 83.174551 | L23: =K23/K$5 -> 0.0048682372 | M23: =K23-I23 -> 6.3745512 | N23: =L23-J23 -> 0.001948052 | O23: =K23/I23 -> 1.083002
B24: 영업외비용 | C24: =SUM(C25:C27) -> 1657.7971 | D24: =C24/C$5 -> 0.015846789 | E24: =SUM(E25:E27) -> 113.05056 | F24: =E24/E$5 -> 0.012275439 | G24: =SUM(G25:G27) -> 0 | H24: =G24/G$5 -> #DIV/0! | I24: =SUM(I25:I27) -> 329.00167 | J24: =I24/I$5 -> 0.012509711 | K24: =SUM(K25:K27) -> 371.40019 | L24: =K24/K$5 -> 0.02173819 | M24: =SUM(M25:M27) -> 42.398514 | N24: =L24-J24 -> 0.0092284788 | O24: =K24/I24 -> 1.1288702 | P24: 환차손 0.2억, 이자비용 3억
B25: (환차손) | D25: =C25/C$5 -> 0 | E25: ='월계획 '!D102/1000 -> 0 | F25: =E25/E$5 -> 0 | G25: ='월계획 '!D134/1000 -> 0 | H25: =G25/G$5 -> #DIV/0! | I25: ='월계획 '!F102/1000 -> 0 | J25: =I25/I$5 -> 0 | K25: ='월계획 '!F134/1000 -> 17.179297 | L25: =K25/K$5 -> 0.0010055106 | M25: =K25-I25 -> 17.179297 | N25: =L25-J25 -> 0.0010055106 | O25: =K25/I25 -> #DIV/0!
B26: (이자비용) | C26: 1625.0117 | D26: =C26/C$5 -> 0.015533395 | E26: ='월계획 '!D103/1000 -> 106.13954 | F26: =E26/E$5 -> 0.011525016 | G26: ='월계획 '!D135/1000 -> 0 | H26: =G26/G$5 -> #DIV/0! | I26: ='월계획 '!F103/1000 -> 305.45832 | J26: =I26/I$5 -> 0.011614516 | K26: ='월계획 '!F135/1000 -> 335.79798 | L26: =K26/K$5 -> 0.01965438 | M26: =K26-I26 -> 30.339667 | N26: =L26-J26 -> 0.0080398635 | O26: =K26/I26 -> 1.0993251
B27: (환차손외) | C27: 32.785407 | D27: =C27/C$5 -> 0.00031339385 | E27: =SUM('월계획 '!D104:D105)/1000 -> 6.9110174 | F27: =E27/E$5 -> 0.00075042332 | G27: =SUM('월계획 '!D136:D137)/1000 -> 0 | H27: =G27/G$5 -> #DIV/0! | I27: =SUM('월계획 '!F104:F105)/1000 -> 23.543357 | J27: =I27/I$5 -> 0.00089519481 | K27: =SUM('월계획 '!F136:F137)/1000 -> 18.422906 | L27: =K27/K$5 -> 0.0010782995 | M27: =K27-I27 -> -5.1204503 | N27: =L27-J27 -> 0.00018310469 | O27: =K27/I27 -> 0.78250976
B28: 소계 | C28: =C21-C24 -> -1350.5971 | D28: =C28/C$5 -> -0.012910281 | E28: =E21-E24 -> -87.450558 | F28: =E28/E$5 -> -0.0094956987 | G28: =G21-G24 -> 0 | H28: =G28/G$5 -> #DIV/0! | I28: =I21-I24 -> -252.20167 | J28: =I28/I$5 -> -0.009589526 | K28: =K21-K24 -> -174.19603 | L28: =K28/K$5 -> -0.010195758 | M28: =K28-I28 -> 78.005639 | N28: =L28-J28 -> -0.00060623218 | O28: =K28/I28 -> 0.69070134
B29: 경상이익 | C29: =C20+C28 -> 5611.7573 | D29: =C29/C$5 -> 0.053642471 | E29: =(E20+E28) -> 599.79088 | F29: =E29/E$5 -> 0.065127468 | G29: =G20+G28 -> 0 | H29: =G29/G$5 -> #DIV/0! | I29: =I20+I28 -> 1639.6469 | J29: =I29/I$5 -> 0.062344697 | K29: =K20+K28 -> 946.95985 | L29: =K29/K$5 -> 0.055425909 | M29: =K29-I29 -> -692.6871 | N29: =L29-J29 -> -0.0069187881 | O29: =-K29/I29 -> -0.57753887
B30: 경상이익(환차손제외) | C30: =C29+C25-C22 -> 5611.7573 | D30: =C30/C$5 -> 0.053642471 | E30: =E29+E25-E22 -> 599.79088 | F30: =E30/E$5 -> 0.065127468 | G30: =G29+G25-G22 -> 0 | H30: =G30/G$5 -> #DIV/0! | I30: =I29+I25-I22 -> 1639.6469 | J30: =I30/I$5 -> 0.062344697 | K30: =K29+K25-K22 -> 850.10955 | L30: =K30/K$5 -> 0.049757225 | M30: =K30-I30 -> -789.5374 | N30: =L30-J30 -> -0.012587472 | O30: =-K30/I30 -> -0.51847109
B31: ☞ 파워포인트 양식으로 옮기기 (1.엑셀에서 범위설정 "복사" 2. 파워포인트에서 "편집"선택 -> "선택하여 붙여넣기" 선택 -> "그림(확장 메타파일)"형식 저장)
C36: ▣ 재료비 초과 내역 (누계 기준)
C37: 1. 초과 금액
C38: (1) 총 매출액 | E38: =K5 -> 17085.148
C39: (2) 초과 비율 | E39: =N11 -> 0.0076455029
C40: 초과 금액 | E40: =E38*E39 -> 130.62455
C42: 2. 주요 내역 | F42: + 재료비 증가, - 재료비 감소
D43: 내역 | G43: 금액
C44: 리어 단가소급 (22년 M2EL 차종) | G44: 52 | H44: =G44/$E$38 -> 0.0030435792
C45: 전년도 인보이스 (모비스) | G45: 51 | H45: =G45/$E$38 -> 0.0029850488
...

Sheet 생산현황 PT
A1: ○ 2024년 만누르 경영실적
AU3: (단위 : 대)
H4: '24년 | Q4: 24년 당월 | AE4: 24년 누계 | AS4: 연간 달성율
H5: 계 획 | M5: 구성비 | Q5: 계 획 | V5: 실 적 | AA5: 달성율 | AE5: 계 획 | AJ5: 실 적 | AO5: 달성율
A6: 연 간 생 산 계 획 내 림 차 순 | C6: AI3 | H6: 270300 | M6: =H6/$H$17 -> 0.33907022 | AA6: =V6/Q6 -> #DIV/0! | AO6: =AJ6/AE6 -> #DIV/0! | AS6: =AJ6/H6 -> 0
C7: QXI | H7: 163440 | M7: =H7/$H$17 -> 0.20502271 | AA7: =V7/Q7 -> #DIV/0! | AO7: =AJ7/AE7 -> #DIV/0! | AS7: =AJ7/H7 -> 0
C8: SU2 | H8: 163200 | M8: =H8/$H$17 -> 0.20472164 | AA8: =V8/Q8 -> #DIV/0! | AO8: =AJ8/AE8 -> #DIV/0! | AS8: =AJ8/H8 -> 0
C9: BN7 | H9: 90500 | M9: =H9/$H$17 -> 0.11352518 | AA9: =V9/Q9 -> #DIV/0! | AO9: =AJ9/AE9 -> #DIV/0! | AS9: =AJ9/H9 -> 0
C10: BI3 | H10: 77300 | M10: =H10/$H$17 -> 0.096966808 | AA10: =V10/Q10 -> #DIV/0! | AO10: =AJ10/AE10 -> #DIV/0! | AS10: =AJ10/H10 -> 0
C11: PS7 | H11: 32440 | M11: =H11/$H$17 -> 0.040693444 | AA11: =V11/Q11 -> #DIV/0! | AO11: =AJ11/AE11 -> #DIV/0! | AS11: =AJ11/H11 -> 0
M12: =H12/$H$17 -> 0 | AA12: =V12/Q12 -> #DIV/0! | AO12: =AJ12/AE12 -> #DIV/0! | AS12: =AJ12/H12 -> #DIV/0!
M13: =H13/$H$17 -> 0 | AA13: =V13/Q13 -> #DIV/0! | AO13: =AJ13/AE13 -> #DIV/0! | AS13: =AJ13/H13 -> #DIV/0!
M14: =H14/$H$17 -> 0 | AA14: =V14/Q14 -> #DIV/0! | AO14: =AJ14/AE14 -> #DIV/0! | AS14: =AJ14/H14 -> #DIV/0!
M15: =H15/$H$17 -> 0 | AA15: =V15/Q15 -> #DIV/0! | AO15: =AJ15/AE15 -> #DIV/0! | AS15: =AJ15/H15 -> #DIV/0!
M16: =H16/$H$17 -> 0 | AA16: =V16/Q16 -> #DIV/0! | AO16: =AJ16/AE16 -> #DIV/0! | AS16: =AJ16/H16 -> #DIV/0!
C17: 생산 계 | H17: =SUM(H6:H16) -> 797180 | M17: =H17/$H$17 -> 1 | Q17: =SUM(Q6:Q16) -> 0 | V17: =SUM(V6:V16) -> 0 | AA17: =V17/Q17 -> #DIV/0! | AE17: =SUM(AE6:AE16) -> 0 | AJ17: =SUM(AJ6:AJ16) -> 0 | AO17: =AJ17/AE17 -> #DIV/0! | AS17: =AJ17/H17 -> 0

Sheet 경영실적 추이도 PT
A1: ○ 2024년 만누르 경영실적 추이현황
W20: (단위 : 백만원)
A21: 구 분 | F21: '23년 | J21: '24년
F22: 연간 실적 | J22: 연간 목표 | K22: 1월 | L22: 2월 | M22: 3월 | N22: 4월 | O22: 5월 | P22: 6월 | Q22: 7월 | R22: 8월 | S22: 9월 | T22: 10월 | U22: 11월 | V22: 12월 | W22: 누 계
A23: 매출액 (A) | F23: =('월계획 '!B4)/1000 -> 100374.62 | J23: =('월계획 '!B80)/1000 -> 104614.07 | K23: =('월계획 '!H112)/1000 -> 8161.5523 | L23: =('월계획 '!I112)/1000 -> 8923.5955 | M23: =('월계획 '!J112)/1000 -> 0 | N23: =('월계획 '!K112)/1000 -> 0 | O23: =('월계획 '!L112)/1000 -> 0 | P23: =('월계획 '!M112)/1000 -> 0 | Q23: =('월계획 '!N112)/1000 -> 0 | R23: =('월계획 '!O112)/1000 -> 0 | ... V23: =('월계획 '!S112)/1000 -> 0 | W23: =SUM(K23:V23) -> 17085.148
A25: 영업이익 | F25: =('월계획 '!B18)/1000 -> 5580.3287 | J25: =('월계획 '!B95)/1000 -> 6962.3544 | K25: =('월계획 '!H127)/1000 -> 375.01735 | L25: =('월계획 '!I127)/1000 -> 746.13854 | M25: =('월계획 '!J127)/1000 -> 0 | N25: =('월계획 '!K127)/1000 -> 0 | O25: =('월계획 '!L127)/1000 -> 0 | P25: =('월계획 '!M127)/1000 -> 0 | Q25: =('월계획 '!N127)/1000 -> 0 | R25: =('월계획 '!O127)/1000 -> 0 | ... V25: =('월계획 '!S127)/1000 -> 0 | W25: =SUM(K25:V25) -> 1121.1559
F26: =F25/F23 -> 0.055595015 | J26: =J25/J23 -> 0.066552752 | K26: =K25/K23 -> 0.045949267 | L26: =L25/L23 -> 0.083614115 | M26: =M25/M23 -> #DIV/0! | N26: =N25/N23 -> #DIV/0! | O26: =O25/O23 -> #DIV/0! | P26: =P25/P23 -> #DIV/0! | Q26: =Q25/Q23 -> #DIV/0! | ... W26: =W25/W23 -> 0.065621667
A27: 경상이익 | F27: =('월계획 '!B22)/1000 -> 3621.727 | J27: =('월계획 '!B107)/1000 -> 5611.7573 | K27: =('월계획 '!H139)/1000 -> 311.46003 | L27: =('월계획 '!I139)/1000 -> 635.49982 | M27: =('월계획 '!J139)/1000 -> 0 | N27: =('월계획 '!K139)/1000 -> 0 | O27: =('월계획 '!L139)/1000 -> 0 | P27: =('월계획 '!M139)/1000 -> 0 | Q27: =('월계획 '!N139)/1000 -> 0 | R27: =('월계획 '!O139)/1000 -> 0 | ... V27: =('월계획 '!S139)/1000 -> 0 | W27: =SUM(K27:V27) -> 946.95985
F28: =F27/F23 -> 0.036082097 | J28: =J27/J23 -> 0.053642471 | K28: =K27/K23 -> 0.038161862 | L28: =L27/L23 -> 0.071215669 | M28: =M27/M23 -> #DIV/0! | N28: =N27/N23 -> #DIV/0! | O28: =O27/O23 -> #DIV/0! | P28: =P27/P23 -> #DIV/0! | Q28: =Q27/Q23 -> #DIV/0! | ... W28: =W27/W23 -> 0.055425909

Sheet 경영실적 PT
A1: ○ 2024년 만누르 경영실적
AS3: (단위 : 백만원)
A4: 구 분 | H4: '23년 | M4: '24년
H5: 연간 실적 | M5: 연간 계획 | R5: 당 월 | AG5: 누 계
R6: 계 획 | W6: 실 적 | AB6: 차 이 | AG6: 계 획 | AL6: 실 적 | AQ6: 차 이
A7: 매출액 (A) | H7: ='월계획 '!B4/1000 -> 100374.62 | M7: ='월계획 '!B80/1000 -> 104614.07 | R7: ='월계획 '!D80/1000 -> 9209.4917 | W7: ='월계획 '!D112/1000 -> 0 | AB7: =W7-R7 -> -9209.4917 | AG7: ='월계획 '!F80/1000 -> 26299.702 | AL7: ='월계획 '!B112/1000 -> 17085.148 | AQ7: =AL7-AG7 -> -9214.554
A9: 판매원가 | C9: 재료비 | H9: ='월계획 '!B9/1000 -> 81330.816 | M9: ='월계획 '!B86/1000 -> 84123.149 | R9: ='월계획 '!D86/1000 -> 7424.4875 | W9: ='월계획 '!D118/1000 -> 0 | AB9: =W9-R9 -> -7424.4875 | AG9: ='월계획 '!F86/1000 -> 21226.141 | AL9: ='월계획 '!B118/1000 -> 13919.821 | AQ9: =AL9-AG9 -> -7306.32
C10: (B) | H10: =IFERROR(H9/H$7,"") -> 0.81027269 | M10: =IFERROR(M9/M$7,"") -> 0.80412842 | R10: =IFERROR(R9/R$7,"") -> 0.80617777 | W10: =IFERROR(W9/W$7,"") | AB10: =W10-R10 -> #VALUE! | AG10: =IFERROR(AG9/AG$7,"") -> 0.80708676 | AL10: =IFERROR(AL9/AL$7,"") -> 0.81473227 | AQ10: =AL10-AG10 -> 0.0076455029
C11: 노무비 | H11: ='월계획 '!B12/1000 -> 4143.6937 | M11: ='월계획 '!B89/1000 -> 4228.2977 | R11: ='월계획 '!D89/1000 -> 332.22012 | W11: ='월계획 '!D121/1000 -> 0 | AB11: =W11-R11 -> -332.22012 | AG11: ='월계획 '!F89/1000 -> 973.40709 | AL11: ='월계획 '!B121/1000 -> 641.47117 | AQ11: =AL11-AG11 -> -331.93591
C12: (C) | H12: =IFERROR(H11/H$7,"") -> 0.041282284 | M12: =IFERROR(M11/M$7,"") -> 0.040418058 | R12: =IFERROR(R11/R$7,"") -> 0.036073665 | W12: =IFERROR(W11/W$7,"") | AB12: =W12-R12 -> #VALUE! | AG12: =IFERROR(AG11/AG$7,"") -> 0.037012096 | AL12: =IFERROR(AL11/AL$7,"") -> 0.037545544 | AQ12: =AL12-AG12 -> 0.00053344845
C13: 경 비 | H13: ='월계획 '!B15/1000 -> 9319.7854 | M13: ='월계획 '!B92/1000 -> 9300.272 | R13: ='월계획 '!D92/1000 -> 765.54264 | W13: ='월계획 '!D124/1000 -> 0 | AB13: =W13-R13 -> -765.54264 | AG13: ='월계획 '!F92/1000 -> 2208.3049 | AL13: ='월계획 '!B124/1000 -> 1402.6996 | AQ13: =AL13-AG13 -> -805.60534
C14: (D) | H14: =IFERROR(H13/H$7,"") -> 0.092850016 | M14: =IFERROR(M13/M$7,"") -> 0.088900774 | R14: =IFERROR(R13/R$7,"") -> 0.083125396 | W14: =IFERROR(W13/W$7,"") | AB14: =W14-R14 -> #VALUE! | AG14: =IFERROR(AG13/AG$7,"") -> 0.083966918 | AL14: =IFERROR(AL13/AL$7,"") -> 0.082100523 | AQ14: =AL14-AG14 -> -0.0018663955
C15: 계 | H15: =H9+H11+H13 -> 94794.295 | M15: =M9+M11+M13 -> 97651.718 | R15: =R9+R11+R13 -> 8522.2503 | W15: =W9+W11+W13 -> 0 | AB15: =W15-R15 -> -8522.2503 | AG15: =AG9+AG11+AG13 -> 24407.853 | AL15: =AL9+AL11+AL13 -> 15963.992 | AQ15: =AL15-AG15 -> -8443.8613
C16: (E=B+C+D) | H16: =IFERROR(H15/H$7,"") -> 0.94440499 | M16: =IFERROR(M15/M$7,"") -> 0.93344725 | R16: =IFERROR(R15/R$7,"") -> 0.92537683 | W16: =IFERROR(W15/W$7,"") | AB16: =W16-R16 -> #VALUE! | AG16: =IFERROR(AG15/AG$7,"") -> 0.92806578 | AL16: =IFERROR(AL15/AL$7,"") -> 0.93437833 | AQ16: =AL16-AG16 -> 0.0063125559
A17: 영업이익 | H17: =H7-H15 -> 5580.3287 | M17: =M7-M15 -> 6962.3544 | R17: =R7-R15 -> 687.24144 | W17: =W7-W15 -> 0 | AB17: =W17-R17 -> -687.24144 | AG17: =AG7-AG15 -> 1891.8486 | AL17: =AL7-AL15 -> 1121.1559 | AQ17: =AL17-AG17 -> -770.69274
A18: (F=A-E) | H18: =IFERROR(H17/H$7,"") -> 0.055595015 | M18: =IFERROR(M17/M$7,"") -> 0.066552752 | R18: =IFERROR(R17/R$7,"") -> 0.074623167 | W18: =IFERROR(W17/W$7,"") | AB18: =W18-R18 -> #VALUE! | AG18: =IFERROR(AG17/AG$7,"") -> 0.071934223 | AL18: =IFERROR(AL17/AL$7,"") -> 0.065621667 | AQ18: =AL18-AG18 -> -0.0063125559
A19: 영업외수지 | H19: ='월계획 '!B21/1000 -> -1958.6017 | M19: ='월계획 '!B106/1000 -> -1350.5971 | R19: ='월계획 '!D106/1000 -> -87.450558 | W19: ='월계획 '!D138/1000 -> 0 | AB19: =W19-R19 -> 87.450558 | AG19: ='월계획 '!F106/1000 -> -252.20167 | AL19: ='월계획 '!B138/1000 -> -174.19603 | AQ19: =AL19-AG19 -> 78.005639
A20: (G) | H20: =IFERROR(H19/H$7,"") -> -0.019512917 | M20: =IFERROR(M19/M$7,"") -> -0.012910281 | R20: =IFERROR(R19/R$7,"") -> -0.0094956987 | W20: =IFERROR(W19/W$7,"") | AB20: =W20-R20 -> #VALUE! | AG20: =IFERROR(AG19/AG$7,"") -> -0.009589526 | AL20: =IFERROR(AL19/AL$7,"") -> -0.010195758 | AQ20: =AL20-AG20 -> -0.00060623218
A21: 경상이익 | H21: =H17+H19 -> 3621.727 | M21: =M17+M19 -> 5611.7573 | R21: =R17+R19 -> 599.79088 | W21: =W17+W19 -> 0 | AB21: =W21-R21 -> -599.79088 | AG21: =AG17+AG19 -> 1639.6469 | AL21: =AL17+AL19 -> 946.95985 | AQ21: =AL21-AG21 -> -692.6871
A22: (H=F+G) | H22: =IFERROR(H21/H$7,"") -> 0.036082097 | M22: =IFERROR(M21/M$7,"") -> 0.053642471 | R22: =IFERROR(R21/R$7,"") -> 0.065127468 | W22: =IFERROR(W21/W$7,"") | AB22: =W22-R22 -> #VALUE! | AG22: =IFERROR(AG21/AG$7,"") -> 0.062344697 | AL22: =IFERROR(AL21/AL$7,"") -> 0.055425909 | AQ22: =AL22-AG22 -> -0.0069187881
A24: 주) “23년, “24년 년도별 사업계획 환율 적용
AX25: 경영실적 분석 PT 참고 | BA25: 매출액 | BB25: 당월 | BC25: 누계
AX26: (삭제금지) | BA26: =M7 -> 104614.07 | BB26: =R7 -> 9209.4917 | BC26: =AG7 -> 26299.702 | BG26: 계획
BB27: =W7 -> 0 | BC27: =AL7 -> 17085.148 | BG27: 실적
BA28: 노무비
AX29: 직접직 | BA29: ='월계획 '!B90/1000 -> 2846.6259 | BB29: ='월계획 '!D90/1000 -> 222.21474 | BC29: ='월계획 '!F90/1000 -> 647.97444 | BD29: =BA29/BA26 -> 0.027210736 | BE29: =BB29/BB26 -> 0.024128882 | BF29: =BC29/BC26 -> 0.024638091 | BG29: 계획
AX30: 간접직 | BA30: ='월계획 '!B91/1000 -> 1381.6718 | BB30: ='월계획 '!D91/1000 -> 110.00538 | BC30: ='월계획 '!F91/1000 -> 325.43265 | BD30: =BA30/BA26 -> 0.013207322 | BE30: =BB30/BB26 -> 0.011944783 | BF30: =BC30/BC26 -> 0.012374005
AX31: 계 | BA31: =SUM(BA29:BA30) -> 4228.2977 | BB31: =SUM(BB29:BB30) -> 332.22012 | BC31: =SUM(BC29:BC30) -> 973.40709
AX32: 직접직 | BB32: ='월계획 '!D122/1000 -> 0 | BC32: ='월계획 '!F122/1000 -> 424.69515 | BE32: =BB32/BB27 -> #DIV/0! | BF32: =BC32/BC27 -> 0.024857564 | BG32: 실적
AX33: 간접직 | BB33: ='월계획 '!D123/1000 -> 0 | BC33: ='월계획 '!F123/1000 -> 216.77602 | BE33: =BB33/BB27 -> #DIV/0! | BF33: =BC33/BC27 -> 0.012687981
AX34: 계 | BB34: =SUM(BB32:BB33) -> 0 | BC34: =SUM(BC32:BC33) -> 641.47117
BA35: 경비
AX36: 감가 | BA36: ='월계획 '!B93/1000 -> 3532.9484 | BB36: ='월계획 '!D93/1000 -> 267.54299 | BC36: ='월계획 '!F93/1000 -> 763.02838 | BD36: =BA36/BA26 -> 0.033771254 | BE36: =BB36/BB26 -> 0.029050788 | BF36: =BC36/BC26 -> 0.029012815 | BG36: 계획
AX37: 일반 | BA37: ='월계획 '!B94/1000 -> 5767.3236 | BB37: ='월계획 '!D94/1000 -> 497.99965 | BC37: ='월계획 '!F94/1000 -> 1445.2765 | BD37: =BA37/BA26 -> 0.05512952 | BE37: =BB37/BB26 -> 0.054074608 | BF37: =BC37/BC26 -> 0.054954103
AX38: 계 | BA38: =SUM(BA36:BA37) -> 9300.272 | BB38: =SUM(BB36:BB37) -> 765.54264 | BC38: =SUM(BC36:BC37) -> 2208.3049
BB39: ='월계획 '!D125/1000 -> 0 | BC39: ='월계획 '!F125/1000 -> 477.01773 | BE39: =BB39/BB27 -> #DIV/0! | BF39: =BC39/BC27 -> 0.027920023 | BG39: 실적
BB40: ='월계획 '!D126/1000 -> 0 | BC40: ='월계획 '!F126/1000 -> 925.68183 | BE40: =BB40/BB27 -> #DIV/0! | BF40: =BC40/BC27 -> 0.054180499
BB41: =SUM(BB39:BB40) -> 0 | BC41: =SUM(BC39:BC40) -> 1402.6996

Sheet 경영실적 분석 PT 1
B1: ○ 2024년 만누르 실적분석
B4: 구 분 | D4: 추이도 | O4: 실적 분석
B6: 매출액 | O6: ○ 판매가 : ○ 생산량 : ○ 기타 : 계획 대비 실적 100% 달성 • AI3 17%(7.7억), BI3 7%(1억), QXI 6%(3.6억) 계획대비↑ • BN7I -28%(3.3억), PS7 -34%(7억), SU2I -18%(3.4억)↓
B8: 재료비 | O8: ○ 매입가 : ○ 재고수불 : ○ 기타 : 계획 대비 실적 재료비 0.7% ↑ • 리어 단가소급 (22년 M2EL 차종) 52백만 (0.30%) • 전년도 인보이스 (모비스) 51백만 (0.30%) • KD 환율변경 45백만 (0.26%) • 직구매 코일 가격 변동 -29백만 (-0.17%)
B11: 구 분 | D11: 추이도 | O11: 실적 분석
B13: 노무비 | O13: ○ 직접직 노무비 : - 직접직 0.01% ↑(계획 467, 실적 446명→21명↓), 휴일특근 ↑ ○ 간접직 노무비 : - 간접직 0.01% ↓(계획 93, 실적 97명→4명 ↑, 푸네지원)
D15: 항 목 | F15: 당 월 | J15: 누 계 | O15: ○ 세부 차이내용 (주요항목) [노무비 지급인원 기재]
F16: 계 획 | G16: % | H16: 실 적 | I16: % | J16: 계 획 | K16: % | L16: 실 적 | M16: %
D17: 매출액 | F17: ='경영실적 PT'!R7 -> 9209.4917 | G17: =F17/F17 -> 1 | H17: ='경영실적 PT'!W7 -> 0 | I17: 1 | J17: ='경영실적 PT'!AG7 -> 26299.702 | K17: =J17/J17 -> 1 | L17: ='경영실적 PT'!AL7 -> 17085.148 | M17: 1
D18: 직접직 | E18: 금액 | F18: ='경영실적 PT'!BB29 -> 222.21474 | G18: =F18/F17 -> 0.024128882 | H18: ='경영실적 PT'!BB32 -> 0 | I18: =H18/H17 -> #DIV/0! | J18: ='경영실적 PT'!BC29 -> 647.97444 | K18: =J18/J17 -> 0.024638091 | L18: ='경영실적 PT'!BC32 -> 424.69515 | M18: =L18/L17 -> 0.024857564
E19: 인원 | F19: =월지표!D60 -> 461 | H19: =월지표!D25 -> 0 | J19: =월지표!F60 -> 462.66667 | L19: =월지표!F25 -> 436
D20: 인당 노무비 | F20: =F18/F19 -> 0.48202763 | H20: =H18/H19 -> #DIV/0! | J20: =J18/J19 -> 1.4005211 | L20: =L18/L19 -> 0.97407144
D21: 간접직 | E21: 금액 | F21: ='경영실적 PT'!BB30 -> 110.00538 | G21: =F21/F17 -> 0.011944783 | H21: ='경영실적 PT'!BB33 -> 0 | I21: =H21/H17 -> #DIV/0! | J21: ='경영실적 PT'!BC30 -> 325.43265 | K21: =J21/J17 -> 0.012374005 | L21: ='경영실적 PT'!BC33 -> 216.77602 | M21: =L21/L17 -> 0.012687981
E22: 인원 | F22: =월지표!D61 -> 93 | H22: =월지표!D26 -> 0 | J22: =월지표!F61 -> 93 | L22: =월지표!F26 -> 98
D23: 인당 노무비 | F23: =F21/F22 -> 1.1828536 | H23: =H21/H22 -> #DIV/0! | J23: =J21/J22 -> 3.4992758 | L23: =L21/L22 -> 2.2120003
D24: 합 계 | F24: =F18+F21 -> 332.22012 | G24: =F24/F17 -> 0.036073665 | H24: =H18+H21 -> 0 | I24: =H24/H17 -> #DIV/0! | J24: =J18+J21 -> 973.40709 | K24: =J24/J17 -> 0.037012096 | L24: =L18+L21 -> 641.47117 | M24: =L24/L17 -> 0.037545544
B26: 구 분 | D26: 추이도 | O26: 실적 분석
B28: 경 비 | O28: ○ 감가상각비 : - 감가상각비 0.1% ↓ ○ 일반경비 : • 건물 수선비 33백만 ↑ └ KM 캐노피,정화조 10백만, 지붕보수 9백만, 기타 (도로,수도,식당) 14백만 • 복리후생 (체육대회연기, 식대등) 40백만 ↓
D30: 항 목 | F30: 당 월 | J30: 누 계 | O30: ○ 일반경비 세부 차이내용 (주요항목)
F31: 계 획 | G31: % | H31: 실 적 | I31: % | J31: 계 획 | K31: % | L31: 실 적 | M31: %
D32: 매출액 | F32: ='경영실적 PT'!R7 -> 9209.4917 | G32: =F32/F32 -> 1 | H32: ='경영실적 PT'!W7 -> 0 | I32: 1 | J32: ='경영실적 PT'!AG7 -> 26299.702 | K32: =J32/J32 -> 1 | L32: ='경영실적 PT'!AL7 -> 17085.148 | M32: 1
D33: 복리후생비 | F33: =경비!M7 -> 63.449312 | G33: =F33/$F$32 -> 0.0068895564 | H33: =경비!M42 -> 0 | I33: =H33/$H$32 -> #DIV/0! | J33: =경비!C42 -> 205.94794 | K33: =J33/$J$32 -> 0.0078308088 | L33: =경비!E42 -> 102.76455 | M33: =L33/$L$32 -> 0.0060148472 | O33: • 체육대회 연기 (우천) 16백만, 항공료 일정변경 8백만, 식대 12백만 ↓
D34: 운반비 | F34: =경비!M14 -> 52.894171 | G34: =F34/$F$32 -> 0.0057434409 | H34: =경비!M49 -> 0 | I34: =H34/$H$32 -> #DIV/0! | J34: =경비!C49 -> 151.16657 | K34: =J34/$J$32 -> 0.0057478434 | L34: =경비!E49 -> 94.064351 | M34: =L34/$L$32 -> 0.0055056212
D35: 소모품비 | F35: =경비!M16 -> 22.936501 | G35: =F35/$F$32 -> 0.0024905285 | H35: =경비!M51 -> 0 | I35: =H35/$H$32 -> #DIV/0! | J35: =경비!C51 -> 65.498983 | K35: =J35/$J$32 -> 0.0024904839 | L35: =경비!E51 -> 37.6166 | M35: =L35/$L$32 -> 0.0022017135
D36: 여비교통비 | F36: =경비!M21 -> 36.8 | G36: =F36/$F$32 -> 0.0039958774 | H36: =경비!M56 -> 0 | I36: =H36/$H$32 -> #DIV/0! | J36: =경비!C56 -> 110.4 | K36: =J36/$J$32 -> 0.0041977662 | L36: =경비!E56 -> 76.26794 | M36: =L36/$L$32 -> 0.0044639906 | O36: • 푸네출장 항공료 ↑(자재, 공무, 회계)
D37: 접대비 | F37: =경비!M22 -> 0.88 | G37: =F37/$F$32 -> 9.5553591e-05 | H37: =경비!M57 -> 0 | I37: =H37/$H$32 -> #DIV/0! | J37: =경비!C57 -> 2.64 | K37: =J37/$J$32 -> 0.00010038137 | L37: =경비!E57 -> 1.932096 | M37: =L37/$L$32 -> 0.00011308629
D38: 지급임차료 | F38: =경비!M19+경비!M20 -> 4.192 | G38: =F38/$F$32 -> 0.00045518256 | H38: =경비!M54+경비!M55 -> 0 | I38: =H38/$H$32 -> #DIV/0! | J38: =경비!C54+경비!C55 -> 12.576 | K38: =J38/$J$32 -> 0.00047818033 | L38: =경비!E54+경비!E55 -> 8.297856 | M38: =L38/$L$32 -> 0.00048567657
D39: 기 타 | F39: =SUM(경비!M8:M13,경비!M15,경비!M17:M18,경비!M23:M26) -> 318.6272 | G39: =F39/$F$32 -> 0.034597697 | H39: =SUM(경비!M43:M48,경비!M50,경비!M52:M53,경비!M58:M61) -> 0 | I39: =H39/$H$32 -> #DIV/0! | J39: =SUM(경비!C43:C48,경비!C50,경비!C52:C53,경비!C58:C61) -> 900.72922 | K39: =J39/$J$32 -> 0.034248648 | L39: =SUM(경비!E43:E48,경비!E50,경비!E52:E53,경비!E58:E61) -> 604.73844 | M39: =L39/$L$32 -> 0.035395564 | O39: • 매출증가에 따른 로열티 감소 • CMM 머신 검교정 3백만, HMI 협력사 회비 1백만
D40: 합 계 | F40: =SUM(F33:F39) -> 499.77919 | G40: =F40/$F$32 -> 0.054267836 | H40: =SUM(H33:H39) -> 0 | I40: =H40/$H$32 -> #DIV/0! | J40: =SUM(J33:J39) -> 1448.9587 | K40: =J40/$J$32 -> 0.055094112 | L40: =SUM(L33:L39) -> 925.68183 | M40: =L40/$L$32 -> 0.054180499
F42: =경비!M31-F40 -> 0 | H42: =경비!M66-H40 -> 0 | J42: =경비!C66-J40 -> 0 | L42: =경비!E66-L40 -> 0

Sheet 경영실적 분석 PT 2
B1: ○ 2024년 만누르 실적분석
B4: 구 분 | D4: 추이도 | P4: 실적 분석
B6: 투자비 | P6: • Repeat mold, crate, PS7I Lever spring - ₩ 19 M
B8: 미수 채권 | D8: 고객사명 | E8: 계약조건 | F8: 미회수 채권 기간별 현황 | P8: ○ 고객사별 미회수 채권 회수방안 [미회수 기간 산정기준 : 전월말 ~ 인보이스 발생일까지 미회수된 채권] [투자비 채권 포함]
F9: 180일 초과 | H9: 90일 초과 | J9: 60일 초과 | L9: 60일 이내 | N9: 계
F10: 건 | G10: 금액 | H10: 건 | I10: 금액 | J10: 건 | K10: 금액 | L10: 건 | M10: 금액
D11: GD Guna Enterprises | E11: 60 day | N11: =G11+I11+K11+M11 -> 0
D12: HTL - SEAT | E12: 45 day | N12: =G12+I12+K12+M12 -> 0
D13: Lear -Chakan | E13: 45 day | N13: =G13+I13+K13+M13 -> 0
D14: Lear -Plant - II | E14: 45 day | N14: =G14+I14+K14+M14 -> 0
D15: Lear Korea | E15: 45 day | N15: =G15+I15+K15+M15 -> 0
D16: METAL | E16: 45 day | N16: =G16+I16+K16+M16 -> 0
D17: MOBIS NEW | E17: 30 day | N17: =G17+I17+K17+M17 -> 0
D18: MOBIS HYD | E18: 30 day | N18: =G18+I18+K18+M18 -> 0
D19: MOBIS | E19: 45 day | N19: =G19+I19+K19+M19 -> 0
D20: NISSAN | E20: 45 day | N20: =G20+I20+K20+M20 -> 0
D21: P.T INDONESIA | E21: 60 day | N21: =G21+I21+K21+M21 -> 0
D22: SPACK | E22: 74 day | N22: =G22+I22+K22+M22 -> 0
D23: UNO | E23: 64 day | N23: =G23+I23+K23+M23 -> 0
D24: 계 | F24: =SUM(F11:F23) -> 0 | G24: =SUM(G11:G23) -> 0 | H24: =SUM(H11:H23) -> 0 | I24: =SUM(I11:I23) -> 0 | J24: =SUM(J11:J23) -> 0 | K24: =SUM(K11:K23) -> 0 | L24: =SUM(L11:L23) -> 0 | M24: =SUM(M11:M23) -> 0 | N24: =G24+I24+K24+M24 -> 0
N25: ='재무상태표(BS)'!I11/1000000 -> 13508.19

Sheet 월계획 
A1: 1. 2023년 월별 실적 | D1: 금액단위: 천원 | F1: 금액단위: 천원 | S1: (단위 : 천원)
A2: 계정과목명 | B2: 2023년 실적 | H2: 01월 | I2: 02월 | J2: 03월 | K2: 04월 | L2: 05월 | M2: 06월 | N2: 07월 | O2: 8월 | P2: 9월 | Q2: 10월 | R2: 11월 | S2: 12월
B3: 금액 | C3: % | H3: 금액 | I3: 금액 | J3: 금액 | K3: 금액 | L3: 금액 | M3: 금액 | N3: 금액 | O3: 금액 | P3: 금액 | Q3: 금액 | R3: 금액 | S3: 금액
A4: 매출액 | B4: =SUM(B5:B7) -> 1.0037462e+08 | C4: =B4/B$4 -> 1 | H4: =SUM(H5:H7) -> 6548315.7 | I4: =SUM(I5:I7) -> 7413490.3 | J4: =SUM(J5:J7) -> 9699250.2 | K4: =SUM(K5:K7) -> 8218007.9 | L4: =SUM(L5:L7) -> 6778472.2 | M4: =SUM(M5:M7) -> 7590160.3 | N4: =SUM(N5:N7) -> 8245472.7 | O4: =SUM(O5:O7) -> 9253877.5 | ... S4: =SUM(S5:S7) -> 9461147.8
A5: 제품매출 | B5: =SUM(H5:S5) -> 98887360 | C5: =B5/B$4 -> 0.98518287 | H5: 6383694.1 | I5: 7336310.8 | J5: 9617694.1 | K5: 8126464.3 | L5: 6689624.5 | M5: 7418345.6 | N5: 7991683.9 | O5: 9023883.2 | P5: 9062873.6 | Q5: 9021749.7 | R5: 8824854.3 | S5: 9390181.7
A6: 상품매출 | B6: =SUM(H6:S6) -> 769207.5 | C6: =B6/B$4 -> 0.0076633662 | H6: 76046.408 | I6: 99640.495 | J6: 42770.167 | K6: 57065.492 | L6: 39624.304 | M6: 111735.14 | N6: 145284.92 | O6: 152892 | P6: 44148.562
A7: 기타매출 | B7: =SUM(H7:S7) -> 718056.65 | C7: =B7/B$4 -> 0.0071537668 | H7: 88575.146 | I7: -22461.021 | J7: 38785.919 | K7: 34478.077 | L7: 49223.423 | M7: 60079.529 | N7: 108503.81 | O7: 77102.274 | P7: 67307.767 | Q7: 66219.778 | R7: 79275.85 | S7: 70966.104
A8: 판매원가 | B8: =B9+B12+B15 -> 94794295 | C8: =B8/B$4 -> 0.94440499 | H8: =H9+H12+H15 -> 6141476.6 | I8: =I9+I12+I15 -> 7094983.6 | J8: =J9+J12+J15 -> 7885538.5 | K8: =K9+K12+K15 -> 7678849.2 | L8: =L9+L12+L15 -> 6446141.1 | M8: =M9+M12+M15 -> 8016315 | N8: =N9+N12+N15 -> 8141281.1 | O8: =O9+O12+O15 -> 8275436.2 | ... S8: =S9+S12+S15 -> 9250509.4
A9: 재료비 소계 | B9: =B10-B11 -> 81330816 | C9: =B9/B$4 -> 0.81027269 | H9: =H10-H11 -> 5114493.7 | I9: =I10-I11 -> 6011002.4 | J9: =J10-J11 -> 6528654.9 | K9: =K10-K11 -> 6617032.8 | L9: =L10-L11 -> 5514531.4 | M9: =M10-M11 -> 7028115.9 | N9: =N10-N11 -> 7099188.4 | O9: =O10-O11 -> 7205634.2 | ... S9: =S10-S11 -> 7952447.2
A10: (재료비) | B10: =SUM(H10:S10) -> 81932486 | C10: =B10/B$4 -> 0.81626693 | H10: 5291853.5 | I10: 6394995.9 | J10: 6084545.3 | K10: 7054801.3 | L10: 6200127.9 | M10: 7095407 | N10: 6714702.2 | O10: 7260304.6 | P10: 7857460.5 | Q10: 7259194.9 | R10: 7023317.6 | S10: 7695775.2
A11: (재고증감) | B11: =SUM(H11:S11) -> 601669.73 | C11: =B11/B$4 -> 0.0059942414 | H11: 177359.87 | I11: 383993.5 | J11: -444109.63 | K11: 437768.49 | L11: 685596.53 | M11: 67291.136 | N11: -384486.17 | O11: 54670.378 | P11: 383205.71 | Q11: -349600.06 | R11: -153348.04 | S11: -256671.99
A12: 노무비 소계 | B12: =SUM(B13:B14) -> 4143693.7 | C12: =B12/B$4 -> 0.041282284 | H12: =SUM(H13:H14) -> 302856.4 | I12: =SUM(I13:I14) -> 299916.28 | J12: =SUM(J13:J14) -> 374812.02 | K12: =SUM(K13:K14) -> 334554.51 | L12: =SUM(L13:L14) -> 299816.72 | M12: =SUM(M13:M14) -> 329662.28 | N12: =SUM(N13:N14) -> 318342.04 | O12: =SUM(O13:O14) -> 327110.41 | ... S12: =SUM(S13:S14) -> 369855.15
A13: (직접노무비) | B13: =SUM(H13:S13) -> 2779247 | C13: =B13/B$4 -> 0.027688741 | H13: 194052.59 | I13: 194614.52 | J13: 233984.94 | K13: 227545.5 | L13: 197624.39 | M13: 230233.45 | N13: 220691 | O13: 231208.31 | P13: 230500.89 | Q13: 226238.02 | R13: 347085.95 | S13: 245467.41
A14: (간접노무비) | B14: =SUM(H14:S14) -> 1364446.7 | C14: =B14/B$4 -> 0.013593543 | H14: 108803.81 | I14: 105301.76 | J14: 140827.08 | K14: 107009.01 | L14: 102192.33 | M14: 99428.832 | N14: 97651.036 | O14: 95902.101 | P14: 105867.11 | Q14: 118540.52 | R14: 158535.39 | S14: 124387.73
A15: 경비 소계 | B15: =SUM(B16:B17) -> 9319785.4 | C15: =B15/B$4 -> 0.092850016 | H15: =SUM(H16:H17) -> 724126.48 | I15: =SUM(I16:I17) -> 784064.92 | J15: =SUM(J16:J17) -> 982071.58 | K15: =SUM(K16:K17) -> 727261.88 | L15: =SUM(L16:L17) -> 631792.95 | M15: =SUM(M16:M17) -> 658536.84 | N15: =SUM(N16:N17) -> 723750.67 | O15: =SUM(O16:O17) -> 742691.55 | ... S15: =SUM(S16:S17) -> 928207.03
A16: (감가상각비) | B16: =SUM(H16:S16) -> 3605812.5 | C16: =B16/B$4 -> 0.035923546 | H16: 286651.54 | I16: 290178.41 | J16: 387236.78 | K16: 263965.71 | L16: 272835.14 | M16: 265450.22 | N16: 277114.83 | O16: 280523.06 | P16: 274954.32 | Q16: 310213.41 | R16: 306870.42 | S16: 389818.62
A17: (기타경비) | B17: =SUM(H17:S17) -> 5713972.9 | C17: =B17/B$4 -> 0.056926469 | H17: 437474.95 | I17: 493886.5 | J17: 594834.79 | K17: 463296.17 | L17: 358957.81 | M17: 393086.61 | N17: 446635.84 | O17: 462168.5 | P17: 468711.8 | Q17: 519334.51 | R17: 537197.05 | S17: 538388.4
A18: 영업이익 | B18: =B4-B8 -> 5580328.7 | C18: =B18/B$4 -> 0.055595015 | H18: =H4-H8 -> 406839.09 | I18: =I4-I8 -> 318506.63 | J18: =J4-J8 -> 1813711.7 | K18: =K4-K8 -> 539158.7 | L18: =L4-L8 -> 332331.15 | M18: =M4-M8 -> -426154.77 | N18: =N4-N8 -> 104191.58 | O18: =O4-O8 -> 978441.34 | ... S18: =S4-S8 -> 210638.41
A19: 영업외수익 | B19: =SUM(H19:S19) -> 1053653.5 | C19: =B19/B$4 -> 0.01049721 | H19: 82997.527 | I19: 71882.296 | J19: 285238.02 | K19: 79927.602 | L19: 66883.713 | M19: 55034.176 | N19: 114393.65 | O19: 72466.191 | P19: 45907.662 | Q19: 51351.343 | R19: 81539.7 | S19: 46031.653
A20: 영업외비용 | B20: =SUM(H20:S20) -> 3012255.3 | C20: =B20/B$4 -> 0.030010128 | H20: 445599.68 | I20: 533815.86 | J20: 497607.9 | K20: 166072.26 | L20: 86913.321 | M20: 135120.62 | N20: 380630.58 | O20: 162624.72 | P20: 191701.71 | Q20: 74872.431 | R20: 137947.14 | S20: 199349.05
A21: 소계 | B21: =B19-B20 -> -1958601.7 | C21: =B21/B$4 -> -0.019512917 | H21: =H19-H20 -> -362602.16 | I21: =I19-I20 -> -461933.56 | J21: =J19-J20 -> -212369.89 | K21: =K19-K20 -> -86144.66 | L21: =L19-L20 -> -20029.608 | M21: =M19-M20 -> -80086.439 | N21: =N19-N20 -> -266236.93 | O21: =O19-O20 -> -90158.529 | ... S21: =S19-S20 -> -153317.4
A22: 경상이익 | B22: =B18+B21 -> 3621727 | C22: =B22/B$4 -> 0.036082097 | H22: =H18+H21 -> 44236.931 | I22: =I18+I21 -> -143426.94 | J22: =J18+J21 -> 1601341.8 | K22: =K18+K21 -> 453014.04 | L22: =L18+L21 -> 312301.55 | M22: =M18+M21 -> -506241.2 | N22: =N18+N21 -> -162045.35 | O22: =O18+O21 -> 888282.81 | ... S22: =S18+S21 -> 57321.016
B23: 3621727
A24: 2. 2024년 추정 손익계획 ← 계획단가 적용(수립시점 표준)
A25: 계정과목명 | B25: 2024년 추정액 | H25: 01월 | I25: 02월 | J25: 03월 | K25: 04월 | L25: 05월 | M25: 06월 | N25: 07월 | O25: 8월 | P25: 9월 | Q25: 10월 | R25: 11월 | S25: 12월
B26: 금액 | C26: % | H26: 금액 | I26: 금액 | J26: 금액 | K26: 금액 | L26: 금액 | M26: 금액 | N26: 금액 | O26: 금액 | P26: 금액 | Q26: 금액 | R26: 금액 | S26: 금액
A27: 매출액 | B27: =SUM(B28:B31) -> 1.0461407e+08 | C27: =B27/B$4 -> 1.0422363 | H27: =SUM(H28:H31) -> 8200673.2 | I27: =SUM(I28:I31) -> 8889536.9 | J27: =SUM(J28:J31) -> 9209491.7 | K27: =SUM(K28:K31) -> 8543837.1 | L27: =SUM(L28:L31) -> 7186028.8 | M27: =SUM(M28:M31) -> 8889304.6 | N27: =SUM(N28:N31) -> 9603975.8 | O27: =SUM(O28:O31) -> 9249341.9 | ... S27: =SUM(S28:S31) -> 8864750.1
A28: 제품매출 | B28: =SUM(H28:S28) -> 1.0313465e+08 | C28: =B28/B$4 -> 1.0274972 | H28: 8077001.9 | I28: 8767555.2 | J28: 9082515.8 | K28: 8419651.1 | L28: 7075977.9 | M28: 8767755.5 | N28: 9478919.2 | O28: 9126371 | P28: 8419649.8 | Q28: 8767656.3 | R28: 8419750.8 | S28: 8731840.6
A29: 상품매출 | B29: =SUM(H29:S29) -> 1076845.6 | C29: =B29/B$4 -> 0.010728266 | H29: 92223.875 | I29: 88211.743 | J29: 92084.603 | K29: 91612.144 | L29: 82233.956 | M29: 87747.092 | N29: 89478.926 | O29: 88599.773 | P29: 85122.735 | Q29: 93441.169 | R29: 92561.41 | S29: 93528.193
A30: 기타매출 | B30: =SUM(H30:S30) -> 741192.23 | C30: =B30/B$4 -> 0.0073842591 | H30: 58458.81 | I30: 63036.907 | J30: 65151.491 | K30: 60712.321 | L30: 51709.066 | M30: 63069.013 | N30: 67675.513 | O30: 65341.497 | P30: 60712.4 | Q30: 63053.083 | R30: 60728.576 | S30: 61543.549
A31: CR금액 | B31: =SUM(H31:S31) -> -338610.36 | C31: =B31/B$4 -> -0.0033734658 | H31: -27011.361 | I31: -29266.969 | J31: -30260.252 | K31: -28138.418 | L31: -23892.148 | M31: -29266.969 | N31: -32097.89 | O31: -30970.363 | P31: -28138.418 | Q31: -29266.969 | R31: -28138.418 | S31: -22162.189
A32: 판매원가 | B32: =B33+B36+B39 -> 98113298 | C32: =B32/B$4 -> 0.97747114 | H32: =H33+H36+H39 -> 7663729.1 | I32: =I33+I36+I39 -> 8239707.5 | J32: =J33+J36+J39 -> 8538930.1 | K32: =K33+K36+K39 -> 7962255.5 | L32: =L33+L36+L39 -> 6816667.7 | M32: =M33+M36+M39 -> 8277133.1 | N32: =N33+N36+N39 -> 8941670.6 | O32: =O33+O36+O39 -> 8629287.1 | ... S32: =S33+S36+S39 -> 8337625.5
A33: 재료비 소계 | B33: =B34-B35 -> 84496424 | C33: =B33/B$4 -> 0.84181061 | H33: =H34-H35 -> 6629660.1 | I33: =I34-I35 -> 7186415.6 | J33: =J34-J35 -> 7437976.3 | K33: =K34-K35 -> 6900296 | L33: =L34-L35 -> 5804719.5 | M33: =M34-M35 -> 7178994.2 | N33: =N34-N35 -> 7757252 | O33: =O34-O35 -> 7470364.5 | ... S33: =S34-S35 -> 7152684.8
A34: (재료비) | B34: =SUM(H34:S34) -> 84496424 | C34: =B34/B$4 -> 0.84181061 | H34: 6629660.1 | I34: 7186415.6 | J34: 7437976.3 | K34: 6900296 | L34: 5804719.5 | M34: 7178994.2 | N34: 7757252 | O34: 7470364.5 | P34: 6895392.5 | Q34: 7182103.4 | R34: 6900564.5 | S34: 7152684.8
A35: (재고증감) | B35: =SUM(H35:S35) -> 0 | C35: =B35/B$4 -> 0
A36: 노무비 소계 | B36: =SUM(B37:B38) -> 4267357.7 | C36: =B36/B$4 -> 0.042514308 | H36: =SUM(H37:H38) -> 314661.74 | I36: =SUM(I37:I38) -> 328034.36 | J36: =SUM(J37:J38) -> 333631.61 | K36: =SUM(K37:K38) -> 332536.94 | L36: =SUM(L37:L38) -> 308083.86 | M36: =SUM(M37:M38) -> 338974.68 | N36: =SUM(N37:N38) -> 351850.18 | O36: =SUM(O37:O38) -> 345412.43 | ... S36: =SUM(S37:S38) -> 368307.72
A37: (직접노무비) | B37: =SUM(H37:S37) -> 2882185.9 | C37: =B37/B$4 -> 0.028714289 | H37: 207958.28 | I37: 219175.33 | J37: 223499.75 | K37: 224467.84 | L37: 204522.57 | M37: 229778.64 | N37: 240400.22 | O37: 235089.43 | P37: 228806.26 | Q37: 235425.57 | R37: 385844.55 | S37: 247217.49
A38: (간접노무비) | B38: =SUM(H38:S38) -> 1385171.8 | C38: =B38/B$4 -> 0.01380002 | H38: 106703.46 | I38: 108859.03 | J38: 110131.86 | K38: 108069.1 | L38: 103561.29 | M38: 109196.05 | N38: 111449.95 | O38: 110323 | P38: 108069.1 | Q38: 115010.91 | R38: 172707.8 | S38: 121090.23
A39: 경비 소계 | B39: =SUM(B40:B41) -> 9349517 | C39: =B39/B$4 -> 0.093146222 | H39: =SUM(H40:H41) -> 719407.31 | I39: =SUM(I40:I41) -> 725257.59 | J39: =SUM(J40:J41) -> 767322.18 | K39: =SUM(K40:K41) -> 729422.58 | L39: =SUM(L40:L41) -> 703864.36 | M39: =SUM(M40:M41) -> 759164.18 | N39: =SUM(N40:N41) -> 832568.5 | O39: =SUM(O40:O41) -> 813510.2 | ... S39: =SUM(S40:S41) -> 816632.9
A40: (감가상각비) | B40: =SUM(H40:S40) -> 3532948.4 | C40: =B40/B$4 -> 0.035197625 | H40: 248195.19 | I40: 247290.19 | J40: 267542.99 | K40: 257266.54 | L40: 280155.5 | M40: 280457.16 | N40: 325179.25 | O40: 325179.25 | P40: 325179.25 | Q40: 325420.58 | R40: 325541.25 | S40: 325541.25
...

Sheet 투자비
A1: ■ 2024년 투자계획(예산)
M2: 단위 : 천원
A3: 자산유형 | B3: 프로젝트(차종) | C3: 내 용 | D3: 투자비 계획 | I3: 당 월 | K3: 누 계 | M3: 비 고
D4: 금 액 | E4: 1분기 | F4: 2분기 | G4: 3분기 | H4: 4분기 | I4: 계획 | J4: 실적 | K4: 계획 | L4: 실적
A5: 토 지
A6: 건 물
A8: 기계장치 | B8: 공용 | C8: 금형 공정개선 관련 금형신작 및 수정 업무 | D8: =SUM(E8:H8) -> 60000 | E8: =SUM(O47:Q47) -> 18000 | F8: =SUM(R47:T47) -> 18000 | G8: =SUM(U47:W47) -> 18000 | H8: =SUM(X47:Z47) -> 6000 | I8: =P47 -> 6000 | J8: =E74 -> 0 | K8: =SUM(O47:P47) -> 12000 | L8: =SUM(D74:E74) -> 0
A9: 기계장치 | B9: 공용 | C9: 밀링머신 구매 | D9: =SUM(E9:H9) -> 15000 | E9: =SUM(O48:Q48) -> 15000 | F9: =SUM(R48:T48) -> 0 | G9: =SUM(U48:W48) -> 0 | H9: =SUM(X48:Z48) -> 0 | I9: =P48 -> 0 | J9: =E75 -> 0 | K9: =SUM(O48:P48) -> 0 | L9: =SUM(D75:E75) -> 0
A10: 기계장치 | B10: QXI/PS7I/SU2I | C10: 신규라인, 미설치라인 유해GAS 배출기 설치 | D10: =SUM(E10:H10) -> 20000 | E10: =SUM(O49:Q49) -> 0 | F10: =SUM(R49:T49) -> 20000 | G10: =SUM(U49:W49) -> 0 | H10: =SUM(X49:Z49) -> 0 | I10: =P49 -> 0 | J10: =E76 -> 0 | K10: =SUM(O49:P49) -> 0 | L10: =SUM(D76:E76) -> 0
A11: 기계장치 | B11: 공용 | C11: 현대로보트 수리자재 구매(CO2로보트 - 설비 오바홀) | D11: =SUM(E11:H11) -> 30000 | E11: =SUM(O50:Q50) -> 0 | F11: =SUM(R50:T50) -> 10000 | G11: =SUM(U50:W50) -> 20000 | H11: =SUM(X50:Z50) -> 0 | I11: =P50 -> 0 | J11: =E77 -> 0 | K11: =SUM(O50:P50) -> 0 | L11: =SUM(D77:E77) -> 0
A12: 기계장치 | B12: 공용 | C12: 디젤보관장 안전라이센스 등록 | D12: =SUM(E12:H12) -> 7000 | E12: =SUM(O51:Q51) -> 7000 | F12: =SUM(R51:T51) -> 0 | G12: =SUM(U51:W51) -> 0 | H12: =SUM(X51:Z51) -> 0 | I12: =P51 -> 0 | J12: =E78 -> 0 | K12: =SUM(O51:P51) -> 0 | L12: =SUM(D78:E78) -> 0
A13: 기계장치 | B13: 공용 | C13: 24년 공정개선 및 원가절감 세부 추진 계획 관련 개선 투자 비용 (공정개선, 공정용/완성품 PLT 자체제작, 안전팬스 제작,설치 및 공장개선 활동) | D13: =SUM(E13:H13) -> 128000 | E13: =SUM(O52:Q52) -> 16000 | F13: =SUM(R52:T52) -> 48000 | G13: =SUM(U52:W52) -> 48000 | H13: =SUM(X52:Z52) -> 16000 | I13: =P52 -> 0 | J13: =E79 -> 0 | K13: =SUM(O52:P52) -> 0 | L13: =SUM(D79:E79) -> 0
A14: 기계장치 | B14: SU2I | C14: SU2I 다단레치 - 조립 및 검사 전용기 7EA / CO2로보트 1EA | D14: =SUM(E14:H14) -> 1000000 | E14: =SUM(O53:Q53) -> 0 | F14: =SUM(R53:T53) -> 0 | G14: =SUM(U53:W53) -> 1000000 | H14: =SUM(X53:Z53) -> 0 | I14: =P53 -> 0 | J14: =E80 -> 0 | K14: =SUM(O53:P53) -> 0 | L14: =SUM(D80:E80) -> 0
A15: 기계장치 | B15: SU2I | C15: SU2I 다단레치 금형(1 LOT) | D15: =SUM(E15:H15) -> 300000 | E15: =SUM(O54:Q54) -> 0 | F15: =SUM(R54:T54) -> 0 | G15: =SUM(U54:W54) -> 300000 | H15: =SUM(X54:Z54) -> 0 | I15: =P54 -> 0 | J15: =E81 -> 0 | K15: =SUM(O54:P54) -> 0 | L15: =SUM(D81:E81) -> 0
A16: 기계장치 | B16: SU2I EV | C16: SU2I EV 버스바 전용라인(2.6만대 기준) - 조립 및 검사 전용기 6EA | D16: =SUM(E16:H16) -> 1665000 | E16: =SUM(O55:Q55) -> 0 | F16: =SUM(R55:T55) -> 0 | G16: =SUM(U55:W55) -> 1665000 | H16: =SUM(X55:Z55) -> 0 | I16: =P55 -> 0 | J16: =E82 -> 0 | K16: =SUM(O55:P55) -> 0 | L16: =SUM(D82:E82) -> 0
A17: 기계장치 | B17: 공용 | C17: 3톤 지게차 구매(생산팀 지게차 교체) | D17: =SUM(E17:H17) -> 10000 | E17: =SUM(O56:Q56) -> 10000 | F17: =SUM(R56:T56) -> 0 | G17: =SUM(U56:W56) -> 0 | H17: =SUM(X56:Z56) -> 0 | I17: =P56 -> 0 | J17: =E83 -> 0 | K17: =SUM(O56:P56) -> 0 | L17: =SUM(D83:E83) -> 0
A18: 기계장치 | B18: UPS | C18: 에어컨(UPS BATTERY ROOM 설치) | D18: =SUM(E18:H18) -> 8000 | E18: =SUM(O57:Q57) -> 8000 | F18: =SUM(R57:T57) -> 0 | G18: =SUM(U57:W57) -> 0 | H18: =SUM(X57:Z57) -> 0 | I18: =P57 -> 8000 | J18: =E84 -> 0 | K18: =SUM(O57:P57) -> 8000 | L18: =SUM(D84:E84) -> 0
A19: 기계장치 | B19: 공용 | C19: LED 전등 신규 설치 및 노후 제품 교체 | D19: =SUM(E19:H19) -> 12000 | E19: =SUM(O58:Q58) -> 12000 | F19: =SUM(R58:T58) -> 0 | G19: =SUM(U58:W58) -> 0 | H19: =SUM(X58:Z58) -> 0 | I19: =P58 -> 4000 | J19: =E85 -> 0 | K19: =SUM(O58:P58) -> 8000 | L19: =SUM(D85:E85) -> 0
... A27: 기계장치 | B27: 공용 | C27: 프레스 소모품교체(모터베어링 8대분) | D27: =SUM(E27:H27) -> 8000 | E27: =SUM(O66:Q66) -> 0 | F27: =SUM(R66:T66) -> 0 | G27: =SUM(U66:W66) -> 0 | H27: =SUM(X66:Z66) -> 8000 | I27: =P66 -> 0 | J27: =E93 -> 0 | K27: =SUM(O66:P66) -> 0 | L27: =SUM(D93:E93) -> 0
D28: =SUM(E28:H28) -> 0 | J28: =E94 -> 0 | L28: =SUM(D94:E94) -> 0
J29: =E95 -> 19208 | L29: =SUM(D95:E95) -> 19208
A30: 차량운반구 | D30: =SUM(E30:H30) -> 0 | J30: =E96 -> 0 | L30: =SUM(D96:E96) -> 0
A31: 공구와기구 | D31: =SUM(E31:H31) -> 0 | J31: =E97 -> 0 | L31: =SUM(D97:E97) -> 0
A32: 비 품 | B32: 공용 | D32: =SUM(E32:H32) -> 0 | J32: =E98 -> 0 | L32: =SUM(D98:E98) -> 0
A33: 비 품 | B33: 공용 | D33: =SUM(E33:H33) -> 0 | J33: =E99 -> 0 | L33: =SUM(D99:E99) -> 0
A34: 건설중인 자산 | D34: =SUM(E34:H34) -> 0
A35: 금 형 | B35: 공용 | D35: =SUM(E35:H35) -> 0
A36: 무형자산 | B36: 공용 | D36: =SUM(E36:H36) -> 0
A37: 합 계 | D37: =SUM(D5:D36) -> 5804500 | I37: =SUM(I5:I36) -> 18000 | J37: =SUM(J5:J36) -> 19208 | K37: =SUM(K5:K36) -> 36000 | L37: =SUM(L5:L36) -> 19208
A43: 월별 투자비 계획
A45: 프로젝트 or 차종 | B45: 투자내용 | E45: 투자예상액 | F45: 투자기간 | G45: 비 고 | H45: 재분류
B46: 품목(항목) | C46: 수량 | D46: 내 용 | H46: 주관부서 | I46: 투자계정 | J46: 귀속법인 | O46: 1월 | P46: 2월 | Q46: 3월 | R46: 4월 | S46: 5월 | T46: 6월 | U46: 7월 | V46: 8월 | W46: 9월 | X46: 10월 | Y46: 11월 | Z46: 12월
A47: 공용 | B47: 금형 | C47: 6 | D47: 금형 공정개선 관련 금형신작 및 수정 업무 | E47: 60000 | F47: 1~10월 | H47: 금형팀 | I47: 금형 | J47: 인도1공장 | O47: =$E$47/10 -> 6000 | P47: =$E$47/10 -> 6000 | Q47: =$E$47/10 -> 6000 | R47: =$E$47/10 -> 6000 | S47: =$E$47/10 -> 6000 | T47: =$E$47/10 -> 6000 | U47: =$E$47/10 -> 6000 | V47: =$E$47/10 -> 6000 | ... X47: =$E$47/10 -> 6000 | AA47: =SUM(O47:Z47)-E47 -> 0
A48: 공용 | B48: 기계장치 | C48: 1 | D48: 밀링머신 구매 | E48: 15000 | F48: 3월 | H48: 보전팀 | I48: 기계장치 | J48: 인도1공장 | Q48: =E48 -> 15000 | AA48: =SUM(O48:Z48)-E48 -> 0
A49: QXI/PS7I/SU2I | B49: 구축물 | C49: 3 | D49: 신규라인, 미설치라인 유해GAS 배출기 설치 | E49: 20000 | F49: 4월 | H49: 보전팀 | I49: 구축물 | J49: 인도1공장 | R49: =E49 -> 20000 | AA49: =SUM(O49:Z49)-E49 -> 0
A50: 공용 | B50: 기계장치 | C50: 6 | D50: 현대로보트 수리자재 구매(CO2로보트 - 설비 오바홀) | E50: 30000 | F50: 6~9월 | H50: 보전팀 | I50: 기계장치 | J50: 인도1공장 | T50: =$E50/3 -> 10000 | U50: =$E50/3 -> 10000 | V50: =$E50/3 -> 10000 | AA50: =SUM(O50:Z50)-E50 -> 0
A51: 공용 | B51: 안전관리 | C51: 1 | D51: 디젤보관장 안전라이센스 등록 | E51: 7000 | F51: 3월 | H51: 보전팀 | I51: 무형자산 | J51: 인도1공장 | Q51: =E51 -> 7000 | AA51: =SUM(O51:Z51)-E51 -> 0
A52: 공용 | B52: 공정개선 &자체 제작 | C52: 1100 | D52: 24년 공정개선 및 원가절감 세부 추진 계획 관련 개선 투자 비용 (공정개선, 공정용/완성품 PLT 자체제작, 안전팬스 제작,설치 및 공장개선 활동) | E52: 128000 | F52: 3~10월 | H52: 보전팀 | I52: 공구와기구 | J52: 인도1공장 | Q52: =$E$52/8 -> 16000 | R52: =$E$52/8 -> 16000 | S52: =$E$52/8 -> 16000 | T52: =$E$52/8 -> 16000 | U52: =$E$52/8 -> 16000 | V52: =$E$52/8 -> 16000 | W52: =$E$52/8 -> 16000 | X52: =$E$52/8 -> 16000 | AA52: =SUM(O52:Z52)-E52 -> 0
A53: SU2I | B53: 전용기 | C53: 8 | D53: SU2I 다단레치 - 조립 및 검사 전용기 7EA / CO2로보트 1EA | E53: 1000000 | F53: 7월 | H53: 보전팀 | I53: 기계장치 | J53: 인도1공장 | U53: =E53 -> 1000000 | AA53: =SUM(O53:Z53)-E53 -> 0
A54: SU2I | B54: 금형 | C54: 1 | D54: SU2I 다단레치 금형(1 LOT) | E54: 300000 | F54: 7월 | H54: 금형팀 | I54: 금형 | J54: 인도1공장 | U54: =E54 -> 300000 | AA54: =SUM(O54:Z54)-E54 -> 0
...

Sheet 매출매입
A1: ○ 2024년 만누르공장 매출매입(재료비 계획대비 실적)
I2: 단위 : 백만원
A3: 구 분(차종외) | C3: 2024년 3월 계획(누계) | F3: 2024년 3월 실적(누계) | I3: 계획대비 분석
C4: 매출 | D4: 재료비계획 | E4: 비율 | F4: 매출 | G4: 재료비실적 | H4: 비율 | I4: 비율차이 | J4: 주요사유
A5: 영업 매출 | B5: AI3 | C5: =C58/1000 -> 0 | D5: =D58/1000 -> 0 | E5: =D5/C5 -> #DIV/0! | F5: =F58/1000 -> 0 | G5: =G58/1000 -> 0 | H5: =G5/F5 -> #DIV/0! | I5: =H5-E5 -> #DIV/0! | L5: =F5-C5 -> 0 | M5: =L5/C5 -> #DIV/0!
B6: AI3 MOBIS | C6: =C59/1000 -> 0 | D6: =D59/1000 -> 0 | E6: =D6/C6 -> #DIV/0! | F6: =F59/1000 -> 0 | G6: =G59/1000 -> 0 | H6: =G6/F6 -> #DIV/0! | I6: =H6-E6 -> #DIV/0! | L6: =F6-C6 -> 0 | M6: =L6/C6 -> #DIV/0! | N6: =SUM(F5:F6)-SUM(C5:C6) -> 0 | O6: =N6/(C5+C6) -> #DIV/0!
B7: BI3 | C7: =C60/1000 -> 0 | D7: =D60/1000 -> 0 | E7: =D7/C7 -> #DIV/0! | F7: =F60/1000 -> 0 | G7: =G60/1000 -> 0 | H7: =G7/F7 -> #DIV/0! | I7: =H7-E7 -> #DIV/0! | L7: =F7-C7 -> 0 | M7: =L7/C7 -> #DIV/0!
B8: BI3 MOBIS | C8: =C61/1000 -> 0 | D8: =D61/1000 -> 0 | E8: =D8/C8 -> #DIV/0! | F8: =F61/1000 -> 0 | G8: =G61/1000 -> 0 | H8: =G8/F8 -> #DIV/0! | I8: =H8-E8 -> #DIV/0! | L8: =F8-C8 -> 0 | M8: =L8/C8 -> #DIV/0! | N8: =SUM(F7:F8)-SUM(C7:C8) -> 0 | O8: =N8/(C7+C8) -> #DIV/0!
B9: BN7I | C9: =C62/1000 -> 0 | D9: =D62/1000 -> 0 | E9: =D9/C9 -> #DIV/0! | F9: =F62/1000 -> 0 | G9: =G62/1000 -> 0 | H9: =G9/F9 -> #DIV/0! | I9: =H9-E9 -> #DIV/0! | L9: =F9-C9 -> 0 | M9: =L9/C9 -> #DIV/0!
B10: BN7I MOBIS | C10: =C63/1000 -> 0 | D10: =D63/1000 -> 0 | E10: =D10/C10 -> #DIV/0! | F10: =F63/1000 -> 0 | G10: =G63/1000 -> 0 | H10: =G10/F10 -> #DIV/0! | I10: =H10-E10 -> #DIV/0! | L10: =F10-C10 -> 0 | M10: =L10/C10 -> #DIV/0! | N10: =SUM(F9:F10)-SUM(C9:C10) -> 0 | O10: =N10/(C9+C10) -> #DIV/0!
B11: QY | C11: =C64/1000 -> 0 | D11: =D64/1000 -> 0 | E11: =D11/C11 -> #DIV/0! | F11: =F64/1000 -> 0 | G11: =G64/1000 -> 0 | H11: =G11/F11 -> #DIV/0! | I11: =H11-E11 -> #DIV/0! | L11: =F11-C11 -> 0 | M11: =L11/C11 -> #DIV/0!
B12: KY | C12: =C65/1000 -> 0 | D12: =D65/1000 -> 0 | E12: =D12/C12 -> #DIV/0! | F12: =F65/1000 -> 0 | G12: =G65/1000 -> 0 | H12: =G12/F12 -> #DIV/0! | I12: =H12-E12 -> #DIV/0! | L12: =F12-C12 -> 0 | M12: =L12/C12 -> #DIV/0!
B13: L02B | C13: =C66/1000 -> 0 | D13: =D66/1000 -> 0 | E13: =D13/C13 -> #DIV/0! | F13: =F66/1000 -> 0 | G13: =G66/1000 -> 0 | H13: =G13/F13 -> #DIV/0! | I13: =H13-E13 -> #DIV/0! | L13: =F13-C13 -> 0 | M13: =L13/C13 -> #DIV/0!
B14: M2EL | C14: =C67/1000 -> 0 | D14: =D67/1000 -> 0 | E14: =D14/C14 -> #DIV/0! | F14: =F67/1000 -> 0 | G14: =G67/1000 -> 0 | H14: =G14/F14 -> #DIV/0! | I14: =H14-E14 -> #DIV/0! | L14: =F14-C14 -> 0 | M14: =L14/C14 -> #DIV/0!
B15: PS7 | C15: =C68/1000 -> 0 | D15: =D68/1000 -> 0 | E15: =D15/C15 -> #DIV/0! | F15: =F68/1000 -> 0 | G15: =G68/1000 -> 0 | H15: =G15/F15 -> #DIV/0! | I15: =H15-E15 -> #DIV/0! | L15: =F15-C15 -> 0 | M15: =L15/C15 -> #DIV/0!
B16: PS7 MOBIS | C16: =C69/1000 -> 0 | D16: =D69/1000 -> 0 | E16: =D16/C16 -> #DIV/0! | F16: =F69/1000 -> 0 | G16: =G69/1000 -> 0 | H16: =G16/F16 -> #DIV/0! | I16: =H16-E16 -> #DIV/0! | L16: =F16-C16 -> 0 | M16: =L16/C16 -> #DIV/0! | N16: =SUM(F15:F16)-SUM(C15:C16) -> 0 | O16: =N16/(C15+C16) -> #DIV/0!
B17: QXIFL | C17: =C70/1000 -> 0 | D17: =D70/1000 -> 0 | E17: =D17/C17 -> #DIV/0! | F17: =F70/1000 -> 0 | G17: =G70/1000 -> 0 | H17: =G17/F17 -> #DIV/0! | I17: =H17-E17 -> #DIV/0! | L17: =F17-C17 -> 0 | M17: =L17/C17 -> #DIV/0!
B18: QXIFL MOBIS | C18: =C71/1000 -> 0 | D18: =D71/1000 -> 0 | E18: =D18/C18 -> #DIV/0! | F18: =F71/1000 -> 0 | G18: =G71/1000 -> 0 | H18: =G18/F18 -> #DIV/0! | I18: =H18-E18 -> #DIV/0! | L18: =F18-C18 -> 0 | M18: =L18/C18 -> #DIV/0!
B19: SU2I | C19: =C72/1000 -> 0 | D19: =D72/1000 -> 0 | E19: =D19/C19 -> #DIV/0! | F19: =F72/1000 -> 0 | G19: =G72/1000 -> 0 | H19: =G19/F19 -> #DIV/0! | I19: =H19-E19 -> #DIV/0! | L19: =F19-C19 -> 0 | M19: =L19/C19 -> #DIV/0!
B20: SU2I MOBIS | C20: =C73/1000 -> 0 | D20: =D73/1000 -> 0 | E20: =D20/C20 -> #DIV/0! | F20: =F73/1000 -> 0 | G20: =G73/1000 -> 0 | H20: =G20/F20 -> #DIV/0! | I20: =H20-E20 -> #DIV/0! | L20: =F20-C20 -> 0 | M20: =L20/C20 -> #DIV/0! | N20: =SUM(F17:F20)-SUM(C17:C20) -> 0 | O20: =N20/(C17+C18+C19+C20) -> #DIV/0!
B21: SU2i & PS7I | C21: =C74/1000 -> 0 | D21: =D74/1000 -> 0 | E21: =D21/C21 -> #DIV/0! | F21: =F74/1000 -> 0 | G21: =G74/1000 -> 0 | H21: =G21/F21 -> #DIV/0! | I21: =H21-E21 -> #DIV/0! | L21: =F21-C21 -> 0 | M21: =L21/C21 -> #DIV/0!
B22: SU2ID | C22: =C75/1000 -> 0 | D22: =D75/1000 -> 0 | E22: =D22/C22 -> #DIV/0! | F22: =F75/1000 -> 0 | G22: =G75/1000 -> 0 | H22: =G22/F22 -> #DIV/0! | I22: =H22-E22 -> #DIV/0! | L22: =F22-C22 -> 0 | M22: =L22/C22 -> #DIV/0!
B23: SU2I BUSBAR | C23: =C76/1000 -> 0 | D23: =D76/1000 -> 0 | E23: =D23/C23 -> #DIV/0! | F23: =F76/1000 -> 0 | G23: =G76/1000 -> 0 | H23: =G23/F23 -> #DIV/0! | I23: =H23-E23 -> #DIV/0! | L23: =F23-C23 -> 0 | M23: =L23/C23 -> #DIV/0!
C24: =C77/1000 -> 0 | D24: =D77/1000 -> 0 | E24: =D24/C24 -> #DIV/0! | F24: =F77/1000 -> 0 | G24: =G77/1000 -> 0 | H24: =G24/F24 -> #DIV/0! | I24: =H24-E24 -> #DIV/0! | L24: =F24-C24 -> 0 | M24: =L24/C24 -> #DIV/0! | N24: =SUM(F21:F24)-SUM(C21:C24) -> 0 | O24: =N24/(C21+C22+C23+C24) -> #DIV/0!
C25: =C78/1000 -> 0 | D25: =D78/1000 -> 0 | E25: =D25/C25 -> #DIV/0! | F25: =F78/1000 -> 0 | G25: =G78/1000 -> 0 | H25: =G25/F25 -> #DIV/0! | I25: =H25-E25 -> #DIV/0! | L25: =F25-C25 -> 0 | M25: =L25/C25 -> #DIV/0!
B26: AS PART SALES/Purchase | C26: =C79/1000 -> 0 | D26: =D79/1000 -> 0 | E26: =D26/C26 -> #DIV/0! | F26: =F79/1000 -> 0 | G26: =G79/1000 -> 0 | H26: =G26/F26 -> #DIV/0! | I26: =H26-E26 -> #DIV/0! | L26: =F26-C26 -> 0 | M26: =L26/C26 -> #DIV/0!
C27: =C80/1000 -> 0 | D27: =D80/1000 -> 0 | E27: =D27/C27 -> #DIV/0! | F27: =F80/1000 -> 0 | G27: =G80/1000 -> 0 | H27: =G27/F27 -> #DIV/0! | I27: =H27-E27 -> #DIV/0! | L27: =F27-C27 -> 0 | M27: =L27/C27 -> #DIV/0!
C28: =C81/1000 -> 0 | D28: =D81/1000 -> 0 | E28: =D28/C28 -> #DIV/0! | F28: =F81/1000 -> 0 | G28: =G81/1000 -> 0 | H28: =G28/F28 -> #DIV/0! | I28: =H28-E28 -> #DIV/0! | L28: =F28-C28 -> 0 | M28: =L28/C28 -> #DIV/0!
C29: =C82/1000 -> 0 | D29: =D82/1000 -> 0 | E29: =D29/C29 -> #DIV/0! | F29: =F82/1000 -> 0 | G29: =G82/1000 -> 0 | H29: =G29/F29 -> #DIV/0! | I29: =H29-E29 -> #DIV/0! | L29: =F29-C29 -> 0 | M29: =L29/C29 -> #DIV/0!
C30: =C83/1000 -> 0 | D30: =D83/1000 -> 0 | E30: =D30/C30 -> #DIV/0! | F30: =F83/1000 -> 0 | G30: =G83/1000 -> 0 | H30: =G30/F30 -> #DIV/0! | I30: =H30-E30 -> #DIV/0! | L30: =F30-C30 -> 0 | M30: =L30/C30 -> #DIV/0!
C31: =C84/1000 -> 0 | D31: =D84/1000 -> 0 | E31: =D31/C31 -> #DIV/0! | F31: =F84/1000 -> 0 | G31: =G84/1000 -> 0 | H31: =G31/F31 -> #DIV/0! | I31: =H31-E31 -> #DIV/0! | L31: =F31-C31 -> 0 | M31: =L31/C31 -> #DIV/0!
C32: =C85/1000 -> 0 | D32: =D85/1000 -> 0 | E32: =D32/C32 -> #DIV/0! | F32: =F85/1000 -> 0 | G32: =G85/1000 -> 0 | H32: =G32/F32 -> #DIV/0! | I32: =H32-E32 -> #DIV/0! | L32: =F32-C32 -> 0 | M32: =L32/C32 -> #DIV/0!
C33: =C86/1000 -> 0 | D33: =D86/1000 -> 0 | E33: =D33/C33 -> #DIV/0! | F33: =F86/1000 -> 0 | G33: =G86/1000 -> 0 | H33: =G33/F33 -> #DIV/0! | I33: =H33-E33 -> #DIV/0! | L33: =F33-C33 -> 0 | M33: =L33/C33 -> #DIV/0!
B34: 제품재고 증감 | C34: =C87/1000 -> 0 | D34: =D87/1000 -> 0 | E34: =D34/C34 -> #DIV/0! | F34: =F87/1000 -> 0 | G34: =G87/1000 -> 0 | H34: =G34/F34 -> #DIV/0! | I34: =H34-E34 -> #DIV/0! | L34: =F34-C34 -> 0 | M34: =L34/C34 -> #DIV/0!
B35: 기타 | C35: =C88/1000 -> 0 | D35: =D88/1000 -> 0 | E35: =D35/C35 -> #DIV/0! | F35: =F88/1000 -> 0 | G35: =G88/1000 -> 0 | H35: =G35/F35 -> #DIV/0! | I35: =H35-E35 -> #DIV/0! | L35: =F35-C35 -> 0 | M35: =L35/C35 -> #DIV/0!
B36: 스크랩 | C36: =C89/1000 -> 0 | D36: =D89/1000 -> 0 | E36: =D36/C36 -> #DIV/0! | F36: =F89/1000 -> 0 | G36: =G89/1000 -> 0 | H36: =G36/F36 -> #DIV/0! | I36: =H36-E36 -> #DIV/0! | L36: =F36-C36 -> 0 | M36: =L36/C36 -> #DIV/0!
B37: 부자재(CO2 GAS,WIRE) | C37: =C90/1000 -> 0 | D37: =D90/1000 -> 0 | E37: =D37/C37 -> #DIV/0! | F37: =F90/1000 -> 0 | G37: =G90/1000 -> 0 | H37: =G37/F37 -> #DIV/0! | I37: =H37-E37 -> #DIV/0! | L37: =F37-C37 -> 0 | M37: =L37/C37 -> #DIV/0!
B38: 관세(운반비포함) | C38: =C91/1000 -> 0 | D38: =D91/1000 -> 0 | E38: =D38/C38 -> #DIV/0! | F38: =F91/1000 -> 0 | G38: =G91/1000 -> 0 | H38: =G38/F38 -> #DIV/0! | I38: =H38-E38 -> #DIV/0! | L38: =F38-C38 -> 0 | M38: =L38/C38 -> #DIV/0!
B39: CR | C39: =C92/1000 -> 0 | D39: =D92/1000 -> 0 | E39: =D39/C39 -> #DIV/0! | F39: =F92/1000 -> 0 | G39: =G92/1000 -> 0 | H39: =G39/F39 -> #DIV/0! | I39: =H39-E39 -> #DIV/0! | L39: =F39-C39 -> 0 | M39: =L39/C39 -> #DIV/0!
B40: 소 계 | C40: =SUM(C5:C39) -> 0 | D40: =SUM(D5:D39) -> 0 | E40: =D40/C40 -> #DIV/0! | F40: =SUM(F5:F39) -> 0 | G40: =SUM(G5:G39) -> 0 | H40: =G40/F40 -> #DIV/0! | I40: =H40-E40 -> #DIV/0!
...

Sheet 경비
A1: ■ 경비 계정별 월별계획
A2: 1.2023년 실적 및 2024년 계획 | G2: (금액단위 : 백만원) | K2: 1000
A3: 구분 | C3: 2023년 누계실적 | E3: 2024년 누계목표 | G3: 계획대비 분석 | I3: 주요변동사유 | K3: ▶ 월별 실적
C4: 금액 | D4: % | E4: 금액 | F4: % | G4: 증가액 | H4: 증가율 | K4: 1월 | L4: 2월 | M4: 3월 | N4: 4월 | O4: 5월 | P4: 6월 | Q4: 7월 | R4: 8월 | S4: 9월 | T4: 10월 | U4: 11월 | V4: 12월
A5: 매출액 | C5: 100374.62 | D5: =C5/$C$5 -> 1 | E5: =SUM(K5:V5) -> 104614.07 | F5: =E5/$E$5 -> 1 | G5: =E5-C5 -> 4239.4486 | H5: =IFERROR(G5/C5,0) -> 0.042236259 | K5: 8200.6732 | L5: 8889.5369 | M5: 9209.4917 | N5: 8543.8371 | O5: 7186.0288 | P5: 8889.3046 | Q5: 9603.9758 | R5: 9249.3419 | S5: 8537.3465 | T5: 8894.8836 | U5: 8544.9024 | V5: 8864.7501
A6: 구분 | B6: 감가상각비 계 | C6: 3605.8125 | D6: =C6/$C$5 -> 0.035923546 | E6: =SUM(K6:V6) -> 3532.9484 | F6: =E6/$E$5 -> 0.033771254 | G6: =E6-C6 -> -72.864083 | H6: =IFERROR(G6/C6,0) -> -0.020207397 | K6: 248.19519 | L6: 247.29019 | M6: 267.54299 | N6: 257.26654 | O6: 280.1555 | P6: 280.45716 | Q6: 325.17925 | R6: 325.17925 | S6: 325.17925 | T6: 325.42058 | U6: 325.54125 | V6: 325.54125
A7: 금액순정렬 | B7: 복리후생비 | C7: 793.09034 | D7: =C7/$C$5 -> 0.0079013033 | E7: =SUM(K7:V7) -> 859.34374 | F7: =E7/$E$5 -> 0.0082144182 | G7: =E7-C7 -> 66.253401 | H7: =IFERROR(G7/C7,0) -> 0.083538277 | K7: 81.449312 | L7: 61.049312 | M7: 63.449312 | N7: 67.449312 | O7: 72.921312 | P7: 59.449312 | Q7: 61.529312 | R7: 57.849312 | S7: 57.849312 | T7: 145.44931 | U7: 67.449312 | V7: 63.449312
B8: 전력비 | C8: 656.77886 | D8: =C8/$C$5 -> 0.006543276 | E8: =SUM(K8:V8) -> 732.29851 | F8: =E8/$E$5 -> 0.007 | G8: =E8-C8 -> 75.519644 | H8: =IFERROR(G8/C8,0) -> 0.11498489 | K8: 57.404712 | L8: 62.226758 | M8: 64.466442 | N8: 59.80686 | O8: 50.302202 | P8: 62.225132 | Q8: 67.22783 | R8: 64.745393 | S8: 59.761425 | T8: 62.264185 | U8: 59.814317 | V8: 62.053251
B9: 발전기사용료 | C9: 193.65639 | D9: =C9/$C$5 -> 0.0019293361 | E9: =SUM(K9:V9) -> 209.22815 | F9: =E9/$E$5 -> 0.002 | G9: =E9-C9 -> 15.571758 | H9: =IFERROR(G9/C9,0) -> 0.080409215 | K9: 16.401346 | L9: 17.779074 | M9: 18.418983 | N9: 17.087674 | O9: 14.372058 | P9: 17.778609 | Q9: 19.207952 | R9: 18.498684 | S9: 17.074693 | T9: 17.789767 | U9: 17.089805 | V9: 17.7295
B10: 수도광열비 | C10: 37.54832 | D10: =C10/$C$5 -> 0.0003740818 | E10: =SUM(K10:V10) -> 32.8 | F10: =E10/$E$5 -> 0.00031353334 | G10: =E10-C10 -> -4.74832 | H10: =IFERROR(G10/C10,0) -> -0.12645892 | K10: 2.4 | L10: 2.4 | M10: 3.2 | N10: 3.2 | O10: 3.2 | P10: 3.2 | Q10: 3.2 | R10: 2.4 | S10: 2.4 | T10: 2.4 | U10: 2.4 | V10: 2.4
B11: 기술지원료 | C11: 1543.7159 | D11: =C11/$C$5 -> 0.015379544 | E11: =SUM(K11:V11) -> 1768.9329 | F11: =E11/$E$5 -> 0.01690913 | G11: =E11-C11 -> 225.21701 | H11: =IFERROR(G11/C11,0) -> 0.14589278 | K11: 138.65496 | L11: 150.33291 | M11: 155.75512 | N11: 144.47279 | O11: 121.46101 | P11: 150.32842 | Q11: 162.45828 | R11: 156.447 | S11: 144.36245 | T11: 150.42353 | U11: 144.49063 | V11: 149.74584
B12: 수선비 - 장비 | C12: 582.56654 | D12: =C12/$C$5 -> 0.0058039225 | E12: =SUM(K12:V12) -> 523.07036 | F12: =E12/$E$5 -> 0.005 | G12: =E12-C12 -> -59.496173 | H12: =IFERROR(G12/C12,0) -> -0.10212769 | K12: 41.003366 | L12: 44.447685 | M12: 46.047458 | N12: 42.719186 | O12: 35.930144 | P12: 44.446523 | Q12: 48.019879 | R12: 46.24671 | S12: 42.686732 | T12: 44.474418 | U12: 42.724512 | V12: 44.323751
B13: 기타수선비 - 건물등 | C13: 280.53107 | D13: =C13/$C$5 -> 0.0027948406 | E13: =SUM(K13:V13) -> 88.32 | F13: =E13/$E$5 -> 0.00084424588 | G13: =E13-C13 -> -192.21107 | H13: =IFERROR(G13/C13,0) -> -0.68516857 | K13: 7.36 | L13: 7.36 | M13: 7.36 | N13: 7.36 | O13: 7.36 | P13: 7.36 | Q13: 7.36 | R13: 7.36 | S13: 7.36 | T13: 7.36 | U13: 7.36 | V13: 7.36
